Workbook

Sheet CONFIG
A1: การตั้งค่าการออกบิล
A2: ปี (ค.ศ.) | B2: 2026
A3: เดือน (1-12) | B3: 1
A5: บัญชีรับเงิน (default) | B5: ACC001
A6: กฎ billing (default) | B6: DEFAULT
A7: โหมดน้ำ (default) | B7: NORMAL
A8: โหมดไฟ (default) | B8: NORMAL
A10: อัตราน้ำ fallback (บาท/หน่วย) | B10: 20
A11: ค่าน้ำขั้นต่ำ fallback (บาท) | B11: 120
A13: อัตราไฟ fallback (บาท/หน่วย) | B13: 20
A14: ค่าไฟขั้นต่ำ fallback (บาท) | B14: 65

Sheet ACCOUNTS
A1: บัญชีรับเงิน (ACCOUNTS)
A2: id | B2: account_name | C2: bank | D2: account_number | E2: is_default | F2: note
A3: รหัส | B3: ชื่อบัญชี | C3: ธนาคาร | D3: หมายเลขบัญชี | E3: ค่าเริ่มต้น | F3: หมายเหตุ
A4: ACC001 | B4: บัญชีชั้น 1 | C4: กสิกรไทย | D4: xxx-x-xxxxx-x | E4: YES | F4: ชั้น 1
A5: ACC002 | B5: บัญชีชั้น 2 | C5: กสิกรไทย | D5: xxx-x-xxxxx-x | E5: NO | F5: ชั้น 2
A6: ACC003 | B6: บัญชีชั้น 3 | C6: กสิกรไทย | D6: xxx-x-xxxxx-x | E6: NO | F6: ชั้น 3
A7: ACC004 | B7: บัญชีชั้น 4 | C7: กสิกรไทย | D7: xxx-x-xxxxx-x | E7: NO | F7: ชั้น 4
A8: ACC005 | B8: บัญชีชั้น 5 | C8: กสิกรไทย | D8: xxx-x-xxxxx-x | E8: NO | F8: ชั้น 5
A9: ACC006 | B9: บัญชีชั้น 6 | C9: กสิกรไทย | D9: xxx-x-xxxxx-x | E9: NO | F9: ชั้น 6
A10: ACC007 | B10: บัญชีชั้น 7 | C10: กสิกรไทย | D10: xxx-x-xxxxx-x | E10: NO | F10: ชั้น 7
A11: ACC008 | B11: บัญชีชั้น 8 | C11: กสิกรไทย | D11: xxx-x-xxxxx-x | E11: NO | F11: ชั้น 8

Sheet RULES
A1: กฎการคิดค่าน้ำค่าไฟ (RULES)
A2: code | B2: description | C2: water_mode | D2: water_rate | E2: water_min_charge | F2: water_flat_amount | G2: water_s1_upto | H2: water_s1_rate | I2: water_s2_upto | J2: water_s2_rate | K2: water_s3_upto | L2: water_s3_rate | M2: water_fee_mode | N2: water_fee_amount | O2: water_fee_per_unit | P2: electric_mode | Q2: electric_rate | R2: electric_min_charge | S2: electric_flat_amount | T2: electric_s1_upto | U2: electric_s1_rate | V2: electric_s2_upto | W2: electric_s2_rate | X2: electric_s3_upto | Y2: electric_s3_rate | Z2: electric_fee_mode | AA2: electric_fee_amount | AB2: electric_fee_per_unit | AC2: note
A3: รหัส | B3: คำอธิบาย | C3: โหมดน้ำ | D3: อัตราน้ำ | E3: ค่าน้ำขั้นต่ำ | F3: ค่าน้ำ(FLAT) | G3: s1 ถึง | H3: s1 rate | I3: s2 ถึง | J3: s2 rate | K3: s3 ถึง | L3: s3 rate | M3: ค่าบริการน้ำ | N3: จำนวน(FLAT) | O3: ต่อหน่วย | P3: โหมดไฟ | Q3: อัตราไฟ | R3: ค่าไฟขั้นต่ำ | S3: ค่าไฟ(FLAT) | T3: s1 ถึง | U3: s1 rate | V3: s2 ถึง | W3: s2 rate | X3: s3 ถึง | Y3: s3 rate | Z3: ค่าบริการไฟ | AA3: จำนวน(FLAT) | AB3: ต่อหน่วย | AC3: หมายเหตุ
A4: DEFAULT | B4: กฎปกติทั่วไป | C4: NORMAL | D4: 20 | E4: 120 | M4: FLAT | N4: 50 | P4: NORMAL | Q4: 20 | R4: 65 | Z4: FLAT | AA4: 50 | AC4: กฎมาตรฐานทั้งอาคาร
A5: OWNER | B5: ห้องเจ้าของ / ยกเว้นค่าน้ำไฟ | C5: DISABLED | M5: NONE | P5: DISABLED | Z5: NONE | AC5: ห้องเจ้าของ ไม่คิดค่าน้ำและไฟ
A6: STEP_W | B6: น้ำขั้นบันได (ตัวอย่าง) | C6: STEP | E6: 120 | G6: 10 | H6: 15 | I6: 30 | J6: 18 | K6: 999 | L6: 22 | M6: FLAT | N6: 50 | P6: NORMAL | Q6: 20 | R6: 65 | Z6: FLAT | AA6: 50 | AC6: น้ำขั้นบันได 3 ระดับ — ตั้งค่าในคอลัมน์ s1/s2/s3
A7: FREE_UTIL | B7: ฟรีน้ำและไฟ | C7: FLAT | F7: 0 | M7: NONE | P7: FLAT | S7: 0 | Z7: NONE | AC7: ฟรีค่าน้ำและไฟ

Sheet ชั้น_1
A1: ข้อมูลบิล ชั้น 1
A2: room | B2: account_id | C2: rule_code | D2: rent_amount | E2: room_status | F2: water_mode | G2: water_prev | H2: water_curr | I2: water_units | J2: water_units_manual | K2: water_charge | L2: water_fee | M2: water_fee_manual | N2: electric_mode | O2: electric_prev | P2: electric_curr | Q2: electric_units | R2: electric_units_manual | S2: electric_charge | T2: electric_fee | U2: electric_fee_manual | V2: furniture_fee | W2: other_fee | X2: total_due | Y2: note | Z2: check_notes | AA2: _helpers (hidden)
A3: เลขห้อง | B3: บัญชีรับเงิน | C3: กฎ billing | D3: ค่าเช่า (กรอกเอง) | E3: สถานะ | F3: โหมดน้ำ | G3: น้ำก่อน | H3: น้ำหลัง | I3: ใช้น้ำ | J3: units น้ำ(manual) | K3: ค่าน้ำ | L3: ค่าบริการน้ำ | M3: ค่าบริการน้ำ(M) | N3: โหมดไฟ | O3: ไฟก่อน | P3: ไฟหลัง | Q3: ใช้ไฟ | R3: units ไฟ(manual) | S3: ค่าไฟ | T3: ค่าบริการไฟ | U3: ค่าบริการไฟ(M) | V3: ค่าเฟอร์ | W3: อื่นๆ | X3: รวมเงิน | Y3: หมายเหตุ | Z3: ตรวจสอบ
A4: 798/1 | B4: ACC001 | C4: DEFAULT | E4: =IF(OR(D4="",D4=0),"INACTIVE","ACTIVE") | F4: NORMAL | I4: =IF(OR(E4="INACTIVE",H4=""),0,MAX(0,H4-G4)) | K4: =IF(OR(E4="INACTIVE",H4=""),0,IF(AB4="DISABLED",0,IF(AB4="FLAT",AE4,IF(AB4="MANUAL",IF(J4="",0,J4*AC4),IF(AB4="STEP",IF(I4<=AF4,I4*AG4,IF(I4<=AH4,AF4*AG4+(I4-AF4)*AI4,AF4*AG4+(AH4-AF4)*AI4+(I4-AH4)*AK4)),MAX(I4*AC4,AD4)))))) | L4: =IF(OR(E4="INACTIVE",H4=""),0,IF(AL4="NONE",0,IF(AL4="FLAT",AM4,IF(AL4="PER_UNIT",I4*AN4,IF(AL4="MANUAL",IF(M4="",0,M4),0))))) | N4: NORMAL | Q4: =IF(OR(E4="INACTIVE",P4=""),0,MAX(0,P4-O4)) | S4: =IF(OR(E4="INACTIVE",P4=""),0,IF(AO4="DISABLED",0,IF(AO4="FLAT",AR4,IF(AO4="MANUAL",IF(R4="",0,R4*AP4),IF(AO4="STEP",IF(Q4<=AS4,Q4*AT4,IF(Q4<=AU4,AS4*AT4+(Q4-AS4)*AV4,AS4*AT4+(AU4-AS4)*AV4+(Q4-AU4)*AX4)),MAX(Q4*AP4,AQ4)))))) | T4: =IF(OR(E4="INACTIVE",P4=""),0,IF(AY4="NONE",0,IF(AY4="FLAT",AZ4,IF(AY4="PER_UNIT",Q4*BA4,IF(AY4="MANUAL",IF(U4="",0,U4),0))))) | X4: =IF(E4="INACTIVE",0,D4+K4+L4+S4+T4+IF(V4="",0,V4)+IF(W4="",0,W4)) | Z4: =IF(E4="INACTIVE","_",IF(AND(G4>0,H4>0,H4<G4),"[!]น้ำ reset ","")&IF(AND(O4>0,P4>0,P4<O4),"[!]ไฟ reset ","")&IF(AND(F4="MANUAL",J4=""),"[X]units น้ำ ","")&IF(AND(N4="MANUAL",R4=""),"[X]units ไฟ ","")&IF(D4=0,"[!]ค่าเช่า=0","")) | AA4: =IF(C4<>"",C4,CONFIG!$B$6) | AB4: =IF(F4<>"",F4,IFERROR(VLOOKUP(AA4,RULES!$A:$C,3,0),CONFIG!$B$7)) | AC4: =IF(IFERROR(VLOOKUP(AA4,RULES!$A:$D,4,0),"")="",CONFIG!$B$10,VLOOKUP(AA4,RULES!$A:$D,4,0)) | AD4: =IF(IFERROR(VLOOKUP(AA4,RULES!$A:$E,5,0),"")="",CONFIG!$B$11,VLOOKUP(AA4,RULES!$A:$E,5,0)) | AE4: =IFERROR(VLOOKUP(AA4,RULES!$A:$F,6,0)*1,0) | AF4: =IFERROR(VLOOKUP(AA4,RULES!$A:$G,7,0)*1,0) | AG4: =IFERROR(VLOOKUP(AA4,RULES!$A:$H,8,0)*1,0) | AH4: =IFERROR(VLOOKUP(AA4,RULES!$A:$I,9,0)*1,0) | AI4: =IFERROR(VLOOKUP(AA4,RULES!$A:$J,10,0)*1,0) | AJ4: =IFERROR(IF(VLOOKUP(AA4,RULES!$A:$K,11,0)="",999999,VLOOKUP(AA4,RULES!$A:$K,11,0)*1),999999) | AK4: =IFERROR(VLOOKUP(AA4,RULES!$A:$L,12,0)*1,0) | AL4: =IFERROR(VLOOKUP(AA4,RULES!$A:$M,13,0),"NONE") | AM4: =IFERROR(VLOOKUP(AA4,RULES!$A:$N,14,0)*1,0) | AN4: =IFERROR(VLOOKUP(AA4,RULES!$A:$O,15,0)*1,0) | AO4: =IF(N4<>"",N4,IFERROR(VLOOKUP(AA4,RULES!$A:$P,16,0),CONFIG!$B$8)) | AP4: =IF(IFERROR(VLOOKUP(AA4,RULES!$A:$Q,17,0),"")="",CONFIG!$B$13,VLOOKUP(AA4,RULES!$A:$Q,17,0)) | AQ4: =IF(IFERROR(VLOOKUP(AA4,RULES!$A:$R,18,0),"")="",CONFIG!$B$14,VLOOKUP(AA4,RULES!$A:$R,18,0)) | AR4: =IFERROR(VLOOKUP(AA4,RULES!$A:$S,19,0)*1,0) | AS4: =IFERROR(VLOOKUP(AA4,RULES!$A:$T,20,0)*1,0) | AT4: =IFERROR(VLOOKUP(AA4,RULES!$A:$U,21,0)*1,0) | AU4: =IFERROR(VLOOKUP(AA4,RULES!$A:$V,22,0)*1,0) | AV4: =IFERROR(VLOOKUP(AA4,RULES!$A:$W,23,0)*1,0) | AW4: =IFERROR(IF(VLOOKUP(AA4,RULES!$A:$X,24,0)="",999999,VLOOKUP(AA4,RULES!$A:$X,24,0)*1),999999) | AX4: =IFERROR(VLOOKUP(AA4,RULES!$A:$Y,25,0)*1,0) | AY4: =IFERROR(VLOOKUP(AA4,RULES!$A:$Z,26,0),"NONE") | AZ4: =IFERROR(VLOOKUP(AA4,RULES!$A:$AA,27,0)*1,0) | BA4: =IFERROR(VLOOKUP(AA4,RULES!$A:$AB,28,0)*1,0)
A5: 798/2 | B5: ACC001 | C5: DEFAULT | E5: =IF(OR(D5="",D5=0),"INACTIVE","ACTIVE") | F5: NORMAL | I5: =IF(OR(E5="INACTIVE",H5=""),0,MAX(0,H5-G5)) | K5: =IF(OR(E5="INACTIVE",H5=""),0,IF(AB5="DISABLED",0,IF(AB5="FLAT",AE5,IF(AB5="MANUAL",IF(J5="",0,J5*AC5),IF(AB5="STEP",IF(I5<=AF5,I5*AG5,IF(I5<=AH5,AF5*AG5+(I5-AF5)*AI5,AF5*AG5+(AH5-AF5)*AI5+(I5-AH5)*AK5)),MAX(I5*AC5,AD5)))))) | L5: =IF(OR(E5="INACTIVE",H5=""),0,IF(AL5="NONE",0,IF(AL5="FLAT",AM5,IF(AL5="PER_UNIT",I5*AN5,IF(AL5="MANUAL",IF(M5="",0,M5),0))))) | N5: NORMAL | Q5: =IF(OR(E5="INACTIVE",P5=""),0,MAX(0,P5-O5)) | S5: =IF(OR(E5="INACTIVE",P5=""),0,IF(AO5="DISABLED",0,IF(AO5="FLAT",AR5,IF(AO5="MANUAL",IF(R5="",0,R5*AP5),IF(AO5="STEP",IF(Q5<=AS5,Q5*AT5,IF(Q5<=AU5,AS5*AT5+(Q5-AS5)*AV5,AS5*AT5+(AU5-AS5)*AV5+(Q5-AU5)*AX5)),MAX(Q5*AP5,AQ5)))))) | T5: =IF(OR(E5="INACTIVE",P5=""),0,IF(AY5="NONE",0,IF(AY5="FLAT",AZ5,IF(AY5="PER_UNIT",Q5*BA5,IF(AY5="MANUAL",IF(U5="",0,U5),0))))) | X5: =IF(E5="INACTIVE",0,D5+K5+L5+S5+T5+IF(V5="",0,V5)+IF(W5="",0,W5)) | Z5: =IF(E5="INACTIVE","_",IF(AND(G5>0,H5>0,H5<G5),"[!]น้ำ reset ","")&IF(AND(O5>0,P5>0,P5<O5),"[!]ไฟ reset ","")&IF(AND(F5="MANUAL",J5=""),"[X]units น้ำ ","")&IF(AND(N5="MANUAL",R5=""),"[X]units ไฟ ","")&IF(D5=0,"[!]ค่าเช่า=0","")) | AA5: =IF(C5<>"",C5,CONFIG!$B$6) | AB5: =IF(F5<>"",F5,IFERROR(VLOOKUP(AA5,RULES!$A:$C,3,0),CONFIG!$B$7)) | AC5: =IF(IFERROR(VLOOKUP(AA5,RULES!$A:$D,4,0),"")="",CONFIG!$B$10,VLOOKUP(AA5,RULES!$A:$D,4,0)) | AD5: =IF(IFERROR(VLOOKUP(AA5,RULES!$A:$E,5,0),"")="",CONFIG!$B$11,VLOOKUP(AA5,RULES!$A:$E,5,0)) | AE5: =IFERROR(VLOOKUP(AA5,RULES!$A:$F,6,0)*1,0) | AF5: =IFERROR(VLOOKUP(AA5,RULES!$A:$G,7,0)*1,0) | AG5: =IFERROR(VLOOKUP(AA5,RULES!$A:$H,8,0)*1,0) | AH5: =IFERROR(VLOOKUP(AA5,RULES!$A:$I,9,0)*1,0) | AI5: =IFERROR(VLOOKUP(AA5,RULES!$A:$J,10,0)*1,0) | AJ5: =IFERROR(IF(VLOOKUP(AA5,RULES!$A:$K,11,0)="",999999,VLOOKUP(AA5,RULES!$A:$K,11,0)*1),999999) | AK5: =IFERROR(VLOOKUP(AA5,RULES!$A:$L,12,0)*1,0) | AL5: =IFERROR(VLOOKUP(AA5,RULES!$A:$M,13,0),"NONE") | AM5: =IFERROR(VLOOKUP(AA5,RULES!$A:$N,14,0)*1,0) | AN5: =IFERROR(VLOOKUP(AA5,RULES!$A:$O,15,0)*1,0) | AO5: =IF(N5<>"",N5,IFERROR(VLOOKUP(AA5,RULES!$A:$P,16,0),CONFIG!$B$8)) | AP5: =IF(IFERROR(VLOOKUP(AA5,RULES!$A:$Q,17,0),"")="",CONFIG!$B$13,VLOOKUP(AA5,RULES!$A:$Q,17,0)) | AQ5: =IF(IFERROR(VLOOKUP(AA5,RULES!$A:$R,18,0),"")="",CONFIG!$B$14,VLOOKUP(AA5,RULES!$A:$R,18,0)) | AR5: =IFERROR(VLOOKUP(AA5,RULES!$A:$S,19,0)*1,0) | AS5: =IFERROR(VLOOKUP(AA5,RULES!$A:$T,20,0)*1,0) | AT5: =IFERROR(VLOOKUP(AA5,RULES!$A:$U,21,0)*1,0) | AU5: =IFERROR(VLOOKUP(AA5,RULES!$A:$V,22,0)*1,0) | AV5: =IFERROR(VLOOKUP(AA5,RULES!$A:$W,23,0)*1,0) | AW5: =IFERROR(IF(VLOOKUP(AA5,RULES!$A:$X,24,0)="",999999,VLOOKUP(AA5,RULES!$A:$X,24,0)*1),999999) | AX5: =IFERROR(VLOOKUP(AA5,RULES!$A:$Y,25,0)*1,0) | AY5: =IFERROR(VLOOKUP(AA5,RULES!$A:$Z,26,0),"NONE") | AZ5: =IFERROR(VLOOKUP(AA5,RULES!$A:$AA,27,0)*1,0) | BA5: =IFERROR(VLOOKUP(AA5,RULES!$A:$AB,28,0)*1,0)
A6: 798/3 | B6: ACC001 | C6: DEFAULT | E6: =IF(OR(D6="",D6=0),"INACTIVE","ACTIVE") | F6: NORMAL | I6: =IF(OR(E6="INACTIVE",H6=""),0,MAX(0,H6-G6)) | K6: =IF(OR(E6="INACTIVE",H6=""),0,IF(AB6="DISABLED",0,IF(AB6="FLAT",AE6,IF(AB6="MANUAL",IF(J6="",0,J6*AC6),IF(AB6="STEP",IF(I6<=AF6,I6*AG6,IF(I6<=AH6,AF6*AG6+(I6-AF6)*AI6,AF6*AG6+(AH6-AF6)*AI6+(I6-AH6)*AK6)),MAX(I6*AC6,AD6)))))) | L6: =IF(OR(E6="INACTIVE",H6=""),0,IF(AL6="NONE",0,IF(AL6="FLAT",AM6,IF(AL6="PER_UNIT",I6*AN6,IF(AL6="MANUAL",IF(M6="",0,M6),0))))) | N6: NORMAL | Q6: =IF(OR(E6="INACTIVE",P6=""),0,MAX(0,P6-O6)) | S6: =IF(OR(E6="INACTIVE",P6=""),0,IF(AO6="DISABLED",0,IF(AO6="FLAT",AR6,IF(AO6="MANUAL",IF(R6="",0,R6*AP6),IF(AO6="STEP",IF(Q6<=AS6,Q6*AT6,IF(Q6<=AU6,AS6*AT6+(Q6-AS6)*AV6,AS6*AT6+(AU6-AS6)*AV6+(Q6-AU6)*AX6)),MAX(Q6*AP6,AQ6)))))) | T6: =IF(OR(E6="INACTIVE",P6=""),0,IF(AY6="NONE",0,IF(AY6="FLAT",AZ6,IF(AY6="PER_UNIT",Q6*BA6,IF(AY6="MANUAL",IF(U6="",0,U6),0))))) | X6: =IF(E6="INACTIVE",0,D6+K6+L6+S6+T6+IF(V6="",0,V6)+IF(W6="",0,W6)) | Z6: =IF(E6="INACTIVE","_",IF(AND(G6>0,H6>0,H6<G6),"[!]น้ำ reset ","")&IF(AND(O6>0,P6>0,P6<O6),"[!]ไฟ reset ","")&IF(AND(F6="MANUAL",J6=""),"[X]units น้ำ ","")&IF(AND(N6="MANUAL",R6=""),"[X]units ไฟ ","")&IF(D6=0,"[!]ค่าเช่า=0","")) | AA6: =IF(C6<>"",C6,CONFIG!$B$6) | AB6: =IF(F6<>"",F6,IFERROR(VLOOKUP(AA6,RULES!$A:$C,3,0),CONFIG!$B$7)) | AC6: =IF(IFERROR(VLOOKUP(AA6,RULES!$A:$D,4,0),"")="",CONFIG!$B$10,VLOOKUP(AA6,RULES!$A:$D,4,0)) | AD6: =IF(IFERROR(VLOOKUP(AA6,RULES!$A:$E,5,0),"")="",CONFIG!$B$11,VLOOKUP(AA6,RULES!$A:$E,5,0)) | AE6: =IFERROR(VLOOKUP(AA6,RULES!$A:$F,6,0)*1,0) | AF6: =IFERROR(VLOOKUP(AA6,RULES!$A:$G,7,0)*1,0) | AG6: =IFERROR(VLOOKUP(AA6,RULES!$A:$H,8,0)*1,0) | AH6: =IFERROR(VLOOKUP(AA6,RULES!$A:$I,9,0)*1,0) | AI6: =IFERROR(VLOOKUP(AA6,RULES!$A:$J,10,0)*1,0) | AJ6: =IFERROR(IF(VLOOKUP(AA6,RULES!$A:$K,11,0)="",999999,VLOOKUP(AA6,RULES!$A:$K,11,0)*1),999999) | AK6: =IFERROR(VLOOKUP(AA6,RULES!$A:$L,12,0)*1,0) | AL6: =IFERROR(VLOOKUP(AA6,RULES!$A:$M,13,0),"NONE") | AM6: =IFERROR(VLOOKUP(AA6,RULES!$A:$N,14,0)*1,0) | AN6: =IFERROR(VLOOKUP(AA6,RULES!$A:$O,15,0)*1,0) | AO6: =IF(N6<>"",N6,IFERROR(VLOOKUP(AA6,RULES!$A:$P,16,0),CONFIG!$B$8)) | AP6: =IF(IFERROR(VLOOKUP(AA6,RULES!$A:$Q,17,0),"")="",CONFIG!$B$13,VLOOKUP(AA6,RULES!$A:$Q,17,0)) | AQ6: =IF(IFERROR(VLOOKUP(AA6,RULES!$A:$R,18,0),"")="",CONFIG!$B$14,VLOOKUP(AA6,RULES!$A:$R,18,0)) | AR6: =IFERROR(VLOOKUP(AA6,RULES!$A:$S,19,0)*1,0) | AS6: =IFERROR(VLOOKUP(AA6,RULES!$A:$T,20,0)*1,0) | AT6: =IFERROR(VLOOKUP(AA6,RULES!$A:$U,21,0)*1,0) | AU6: =IFERROR(VLOOKUP(AA6,RULES!$A:$V,22,0)*1,0) | AV6: =IFERROR(VLOOKUP(AA6,RULES!$A:$W,23,0)*1,0) | AW6: =IFERROR(IF(VLOOKUP(AA6,RULES!$A:$X,24,0)="",999999,VLOOKUP(AA6,RULES!$A:$X,24,0)*1),999999) | AX6: =IFERROR(VLOOKUP(AA6,RULES!$A:$Y,25,0)*1,0) | AY6: =IFERROR(VLOOKUP(AA6,RULES!$A:$Z,26,0),"NONE") | AZ6: =IFERROR(VLOOKUP(AA6,RULES!$A:$AA,27,0)*1,0) | BA6: =IFERROR(VLOOKUP(AA6,RULES!$A:$AB,28,0)*1,0)
A7: 798/4 | B7: ACC001 | C7: DEFAULT | E7: =IF(OR(D7="",D7=0),"INACTIVE","ACTIVE") | F7: NORMAL | I7: =IF(OR(E7="INACTIVE",H7=""),0,MAX(0,H7-G7)) | K7: =IF(OR(E7="INACTIVE",H7=""),0,IF(AB7="DISABLED",0,IF(AB7="FLAT",AE7,IF(AB7="MANUAL",IF(J7="",0,J7*AC7),IF(AB7="STEP",IF(I7<=AF7,I7*AG7,IF(I7<=AH7,AF7*AG7+(I7-AF7)*AI7,AF7*AG7+(AH7-AF7)*AI7+(I7-AH7)*AK7)),MAX(I7*AC7,AD7)))))) | L7: =IF(OR(E7="INACTIVE",H7=""),0,IF(AL7="NONE",0,IF(AL7="FLAT",AM7,IF(AL7="PER_UNIT",I7*AN7,IF(AL7="MANUAL",IF(M7="",0,M7),0))))) | N7: NORMAL | Q7: =IF(OR(E7="INACTIVE",P7=""),0,MAX(0,P7-O7)) | S7: =IF(OR(E7="INACTIVE",P7=""),0,IF(AO7="DISABLED",0,IF(AO7="FLAT",AR7,IF(AO7="MANUAL",IF(R7="",0,R7*AP7),IF(AO7="STEP",IF(Q7<=AS7,Q7*AT7,IF(Q7<=AU7,AS7*AT7+(Q7-AS7)*AV7,AS7*AT7+(AU7-AS7)*AV7+(Q7-AU7)*AX7)),MAX(Q7*AP7,AQ7)))))) | T7: =IF(OR(E7="INACTIVE",P7=""),0,IF(AY7="NONE",0,IF(AY7="FLAT",AZ7,IF(AY7="PER_UNIT",Q7*BA7,IF(AY7="MANUAL",IF(U7="",0,U7),0))))) | X7: =IF(E7="INACTIVE",0,D7+K7+L7+S7+T7+IF(V7="",0,V7)+IF(W7="",0,W7)) | Z7: =IF(E7="INACTIVE","_",IF(AND(G7>0,H7>0,H7<G7),"[!]น้ำ reset ","")&IF(AND(O7>0,P7>0,P7<O7),"[!]ไฟ reset ","")&IF(AND(F7="MANUAL",J7=""),"[X]units น้ำ ","")&IF(AND(N7="MANUAL",R7=""),"[X]units ไฟ ","")&IF(D7=0,"[!]ค่าเช่า=0","")) | AA7: =IF(C7<>"",C7,CONFIG!$B$6) | AB7: =IF(F7<>"",F7,IFERROR(VLOOKUP(AA7,RULES!$A:$C,3,0),CONFIG!$B$7)) | AC7: =IF(IFERROR(VLOOKUP(AA7,RULES!$A:$D,4,0),"")="",CONFIG!$B$10,VLOOKUP(AA7,RULES!$A:$D,4,0)) | AD7: =IF(IFERROR(VLOOKUP(AA7,RULES!$A:$E,5,0),"")="",CONFIG!$B$11,VLOOKUP(AA7,RULES!$A:$E,5,0)) | AE7: =IFERROR(VLOOKUP(AA7,RULES!$A:$F,6,0)*1,0) | AF7: =IFERROR(VLOOKUP(AA7,RULES!$A:$G,7,0)*1,0) | AG7: =IFERROR(VLOOKUP(AA7,RULES!$A:$H,8,0)*1,0) | AH7: =IFERROR(VLOOKUP(AA7,RULES!$A:$I,9,0)*1,0) | AI7: =IFERROR(VLOOKUP(AA7,RULES!$A:$J,10,0)*1,0) | AJ7: =IFERROR(IF(VLOOKUP(AA7,RULES!$A:$K,11,0)="",999999,VLOOKUP(AA7,RULES!$A:$K,11,0)*1),999999) | AK7: =IFERROR(VLOOKUP(AA7,RULES!$A:$L,12,0)*1,0) | AL7: =IFERROR(VLOOKUP(AA7,RULES!$A:$M,13,0),"NONE") | AM7: =IFERROR(VLOOKUP(AA7,RULES!$A:$N,14,0)*1,0) | AN7: =IFERROR(VLOOKUP(AA7,RULES!$A:$O,15,0)*1,0) | AO7: =IF(N7<>"",N7,IFERROR(VLOOKUP(AA7,RULES!$A:$P,16,0),CONFIG!$B$8)) | AP7: =IF(IFERROR(VLOOKUP(AA7,RULES!$A:$Q,17,0),"")="",CONFIG!$B$13,VLOOKUP(AA7,RULES!$A:$Q,17,0)) | AQ7: =IF(IFERROR(VLOOKUP(AA7,RULES!$A:$R,18,0),"")="",CONFIG!$B$14,VLOOKUP(AA7,RULES!$A:$R,18,0)) | AR7: =IFERROR(VLOOKUP(AA7,RULES!$A:$S,19,0)*1,0) | AS7: =IFERROR(VLOOKUP(AA7,RULES!$A:$T,20,0)*1,0) | AT7: =IFERROR(VLOOKUP(AA7,RULES!$A:$U,21,0)*1,0) | AU7: =IFERROR(VLOOKUP(AA7,RULES!$A:$V,22,0)*1,0) | AV7: =IFERROR(VLOOKUP(AA7,RULES!$A:$W,23,0)*1,0) | AW7: =IFERROR(IF(VLOOKUP(AA7,RULES!$A:$X,24,0)="",999999,VLOOKUP(AA7,RULES!$A:$X,24,0)*1),999999) | AX7: =IFERROR(VLOOKUP(AA7,RULES!$A:$Y,25,0)*1,0) | AY7: =IFERROR(VLOOKUP(AA7,RULES!$A:$Z,26,0),"NONE") | AZ7: =IFERROR(VLOOKUP(AA7,RULES!$A:$AA,27,0)*1,0) | BA7: =IFERROR(VLOOKUP(AA7,RULES!$A:$AB,28,0)*1,0)
A8: 798/5 | B8: ACC001 | C8: DEFAULT | E8: =IF(OR(D8="",D8=0),"INACTIVE","ACTIVE") | F8: NORMAL | I8: =IF(OR(E8="INACTIVE",H8=""),0,MAX(0,H8-G8)) | K8: =IF(OR(E8="INACTIVE",H8=""),0,IF(AB8="DISABLED",0,IF(AB8="FLAT",AE8,IF(AB8="MANUAL",IF(J8="",0,J8*AC8),IF(AB8="STEP",IF(I8<=AF8,I8*AG8,IF(I8<=AH8,AF8*AG8+(I8-AF8)*AI8,AF8*AG8+(AH8-AF8)*AI8+(I8-AH8)*AK8)),MAX(I8*AC8,AD8)))))) | L8: =IF(OR(E8="INACTIVE",H8=""),0,IF(AL8="NONE",0,IF(AL8="FLAT",AM8,IF(AL8="PER_UNIT",I8*AN8,IF(AL8="MANUAL",IF(M8="",0,M8),0))))) | N8: NORMAL | Q8: =IF(OR(E8="INACTIVE",P8=""),0,MAX(0,P8-O8)) | S8: =IF(OR(E8="INACTIVE",P8=""),0,IF(AO8="DISABLED",0,IF(AO8="FLAT",AR8,IF(AO8="MANUAL",IF(R8="",0,R8*AP8),IF(AO8="STEP",IF(Q8<=AS8,Q8*AT8,IF(Q8<=AU8,AS8*AT8+(Q8-AS8)*AV8,AS8*AT8+(AU8-AS8)*AV8+(Q8-AU8)*AX8)),MAX(Q8*AP8,AQ8)))))) | T8: =IF(OR(E8="INACTIVE",P8=""),0,IF(AY8="NONE",0,IF(AY8="FLAT",AZ8,IF(AY8="PER_UNIT",Q8*BA8,IF(AY8="MANUAL",IF(U8="",0,U8),0))))) | X8: =IF(E8="INACTIVE",0,D8+K8+L8+S8+T8+IF(V8="",0,V8)+IF(W8="",0,W8)) | Z8: =IF(E8="INACTIVE","_",IF(AND(G8>0,H8>0,H8<G8),"[!]น้ำ reset ","")&IF(AND(O8>0,P8>0,P8<O8),"[!]ไฟ reset ","")&IF(AND(F8="MANUAL",J8=""),"[X]units น้ำ ","")&IF(AND(N8="MANUAL",R8=""),"[X]units ไฟ ","")&IF(D8=0,"[!]ค่าเช่า=0","")) | AA8: =IF(C8<>"",C8,CONFIG!$B$6) | AB8: =IF(F8<>"",F8,IFERROR(VLOOKUP(AA8,RULES!$A:$C,3,0),CONFIG!$B$7)) | AC8: =IF(IFERROR(VLOOKUP(AA8,RULES!$A:$D,4,0),"")="",CONFIG!$B$10,VLOOKUP(AA8,RULES!$A:$D,4,0)) | AD8: =IF(IFERROR(VLOOKUP(AA8,RULES!$A:$E,5,0),"")="",CONFIG!$B$11,VLOOKUP(AA8,RULES!$A:$E,5,0)) | AE8: =IFERROR(VLOOKUP(AA8,RULES!$A:$F,6,0)*1,0) | AF8: =IFERROR(VLOOKUP(AA8,RULES!$A:$G,7,0)*1,0) | AG8: =IFERROR(VLOOKUP(AA8,RULES!$A:$H,8,0)*1,0) | AH8: =IFERROR(VLOOKUP(AA8,RULES!$A:$I,9,0)*1,0) | AI8: =IFERROR(VLOOKUP(AA8,RULES!$A:$J,10,0)*1,0) | AJ8: =IFERROR(IF(VLOOKUP(AA8,RULES!$A:$K,11,0)="",999999,VLOOKUP(AA8,RULES!$A:$K,11,0)*1),999999) | AK8: =IFERROR(VLOOKUP(AA8,RULES!$A:$L,12,0)*1,0) | AL8: =IFERROR(VLOOKUP(AA8,RULES!$A:$M,13,0),"NONE") | AM8: =IFERROR(VLOOKUP(AA8,RULES!$A:$N,14,0)*1,0) | AN8: =IFERROR(VLOOKUP(AA8,RULES!$A:$O,15,0)*1,0) | AO8: =IF(N8<>"",N8,IFERROR(VLOOKUP(AA8,RULES!$A:$P,16,0),CONFIG!$B$8)) | AP8: =IF(IFERROR(VLOOKUP(AA8,RULES!$A:$Q,17,0),"")="",CONFIG!$B$13,VLOOKUP(AA8,RULES!$A:$Q,17,0)) | AQ8: =IF(IFERROR(VLOOKUP(AA8,RULES!$A:$R,18,0),"")="",CONFIG!$B$14,VLOOKUP(AA8,RULES!$A:$R,18,0)) | AR8: =IFERROR(VLOOKUP(AA8,RULES!$A:$S,19,0)*1,0) | AS8: =IFERROR(VLOOKUP(AA8,RULES!$A:$T,20,0)*1,0) | AT8: =IFERROR(VLOOKUP(AA8,RULES!$A:$U,21,0)*1,0) | AU8: =IFERROR(VLOOKUP(AA8,RULES!$A:$V,22,0)*1,0) | AV8: =IFERROR(VLOOKUP(AA8,RULES!$A:$W,23,0)*1,0) | AW8: =IFERROR(IF(VLOOKUP(AA8,RULES!$A:$X,24,0)="",999999,VLOOKUP(AA8,RULES!$A:$X,24,0)*1),999999) | AX8: =IFERROR(VLOOKUP(AA8,RULES!$A:$Y,25,0)*1,0) | AY8: =IFERROR(VLOOKUP(AA8,RULES!$A:$Z,26,0),"NONE") | AZ8: =IFERROR(VLOOKUP(AA8,RULES!$A:$AA,27,0)*1,0) | BA8: =IFERROR(VLOOKUP(AA8,RULES!$A:$AB,28,0)*1,0)
A9: 798/6 | B9: ACC001 | C9: DEFAULT | E9: =IF(OR(D9="",D9=0),"INACTIVE","ACTIVE") | F9: NORMAL | I9: =IF(OR(E9="INACTIVE",H9=""),0,MAX(0,H9-G9)) | K9: =IF(OR(E9="INACTIVE",H9=""),0,IF(AB9="DISABLED",0,IF(AB9="FLAT",AE9,IF(AB9="MANUAL",IF(J9="",0,J9*AC9),IF(AB9="STEP",IF(I9<=AF9,I9*AG9,IF(I9<=AH9,AF9*AG9+(I9-AF9)*AI9,AF9*AG9+(AH9-AF9)*AI9+(I9-AH9)*AK9)),MAX(I9*AC9,AD9)))))) | L9: =IF(OR(E9="INACTIVE",H9=""),0,IF(AL9="NONE",0,IF(AL9="FLAT",AM9,IF(AL9="PER_UNIT",I9*AN9,IF(AL9="MANUAL",IF(M9="",0,M9),0))))) | N9: NORMAL | Q9: =IF(OR(E9="INACTIVE",P9=""),0,MAX(0,P9-O9)) | S9: =IF(OR(E9="INACTIVE",P9=""),0,IF(AO9="DISABLED",0,IF(AO9="FLAT",AR9,IF(AO9="MANUAL",IF(R9="",0,R9*AP9),IF(AO9="STEP",IF(Q9<=AS9,Q9*AT9,IF(Q9<=AU9,AS9*AT9+(Q9-AS9)*AV9,AS9*AT9+(AU9-AS9)*AV9+(Q9-AU9)*AX9)),MAX(Q9*AP9,AQ9)))))) | T9: =IF(OR(E9="INACTIVE",P9=""),0,IF(AY9="NONE",0,IF(AY9="FLAT",AZ9,IF(AY9="PER_UNIT",Q9*BA9,IF(AY9="MANUAL",IF(U9="",0,U9),0))))) | X9: =IF(E9="INACTIVE",0,D9+K9+L9+S9+T9+IF(V9="",0,V9)+IF(W9="",0,W9)) | Z9: =IF(E9="INACTIVE","_",IF(AND(G9>0,H9>0,H9<G9),"[!]น้ำ reset ","")&IF(AND(O9>0,P9>0,P9<O9),"[!]ไฟ reset ","")&IF(AND(F9="MANUAL",J9=""),"[X]units น้ำ ","")&IF(AND(N9="MANUAL",R9=""),"[X]units ไฟ ","")&IF(D9=0,"[!]ค่าเช่า=0","")) | AA9: =IF(C9<>"",C9,CONFIG!$B$6) | AB9: =IF(F9<>"",F9,IFERROR(VLOOKUP(AA9,RULES!$A:$C,3,0),CONFIG!$B$7)) | AC9: =IF(IFERROR(VLOOKUP(AA9,RULES!$A:$D,4,0),"")="",CONFIG!$B$10,VLOOKUP(AA9,RULES!$A:$D,4,0)) | AD9: =IF(IFERROR(VLOOKUP(AA9,RULES!$A:$E,5,0),"")="",CONFIG!$B$11,VLOOKUP(AA9,RULES!$A:$E,5,0)) | AE9: =IFERROR(VLOOKUP(AA9,RULES!$A:$F,6,0)*1,0) | AF9: =IFERROR(VLOOKUP(AA9,RULES!$A:$G,7,0)*1,0) | AG9: =IFERROR(VLOOKUP(AA9,RULES!$A:$H,8,0)*1,0) | AH9: =IFERROR(VLOOKUP(AA9,RULES!$A:$I,9,0)*1,0) | AI9: =IFERROR(VLOOKUP(AA9,RULES!$A:$J,10,0)*1,0) | AJ9: =IFERROR(IF(VLOOKUP(AA9,RULES!$A:$K,11,0)="",999999,VLOOKUP(AA9,RULES!$A:$K,11,0)*1),999999) | AK9: =IFERROR(VLOOKUP(AA9,RULES!$A:$L,12,0)*1,0) | AL9: =IFERROR(VLOOKUP(AA9,RULES!$A:$M,13,0),"NONE") | AM9: =IFERROR(VLOOKUP(AA9,RULES!$A:$N,14,0)*1,0) | AN9: =IFERROR(VLOOKUP(AA9,RULES!$A:$O,15,0)*1,0) | AO9: =IF(N9<>"",N9,IFERROR(VLOOKUP(AA9,RULES!$A:$P,16,0),CONFIG!$B$8)) | AP9: =IF(IFERROR(VLOOKUP(AA9,RULES!$A:$Q,17,0),"")="",CONFIG!$B$13,VLOOKUP(AA9,RULES!$A:$Q,17,0)) | AQ9: =IF(IFERROR(VLOOKUP(AA9,RULES!$A:$R,18,0),"")="",CONFIG!$B$14,VLOOKUP(AA9,RULES!$A:$R,18,0)) | AR9: =IFERROR(VLOOKUP(AA9,RULES!$A:$S,19,0)*1,0) | AS9: =IFERROR(VLOOKUP(AA9,RULES!$A:$T,20,0)*1,0) | AT9: =IFERROR(VLOOKUP(AA9,RULES!$A:$U,21,0)*1,0) | AU9: =IFERROR(VLOOKUP(AA9,RULES!$A:$V,22,0)*1,0) | AV9: =IFERROR(VLOOKUP(AA9,RULES!$A:$W,23,0)*1,0) | AW9: =IFERROR(IF(VLOOKUP(AA9,RULES!$A:$X,24,0)="",999999,VLOOKUP(AA9,RULES!$A:$X,24,0)*1),999999) | AX9: =IFERROR(VLOOKUP(AA9,RULES!$A:$Y,25,0)*1,0) | AY9: =IFERROR(VLOOKUP(AA9,RULES!$A:$Z,26,0),"NONE") | AZ9: =IFERROR(VLOOKUP(AA9,RULES!$A:$AA,27,0)*1,0) | BA9: =IFERROR(VLOOKUP(AA9,RULES!$A:$AB,28,0)*1,0)
A10: 798/7 | B10: ACC001 | C10: DEFAULT | E10: =IF(OR(D10="",D10=0),"INACTIVE","ACTIVE") | F10: NORMAL | I10: =IF(OR(E10="INACTIVE",H10=""),0,MAX(0,H10-G10)) | K10: =IF(OR(E10="INACTIVE",H10=""),0,IF(AB10="DISABLED",0,IF(AB10="FLAT",AE10,IF(AB10="MANUAL",IF(J10="",0,J10*AC10),IF(AB10="STEP",IF(I10<=AF10,I10*AG10,IF(I10<=AH10,AF10*AG10+(I10-AF10)*AI10,AF10*AG10+(AH10-AF10)*AI10+(I10-AH10)*AK10)),MAX(I10*AC10,AD10)))))) | L10: =IF(OR(E10="INACTIVE",H10=""),0,IF(AL10="NONE",0,IF(AL10="FLAT",AM10,IF(AL10="PER_UNIT",I10*AN10,IF(AL10="MANUAL",IF(M10="",0,M10),0))))) | N10: NORMAL | Q10: =IF(OR(E10="INACTIVE",P10=""),0,MAX(0,P10-O10)) | S10: =IF(OR(E10="INACTIVE",P10=""),0,IF(AO10="DISABLED",0,IF(AO10="FLAT",AR10,IF(AO10="MANUAL",IF(R10="",0,R10*AP10),IF(AO10="STEP",IF(Q10<=AS10,Q10*AT10,IF(Q10<=AU10,AS10*AT10+(Q10-AS10)*AV10,AS10*AT10+(AU10-AS10)*AV10+(Q10-AU10)*AX10)),MAX(Q10*AP10,AQ10)))))) | T10: =IF(OR(E10="INACTIVE",P10=""),0,IF(AY10="NONE",0,IF(AY10="FLAT",AZ10,IF(AY10="PER_UNIT",Q10*BA10,IF(AY10="MANUAL",IF(U10="",0,U10),0))))) | X10: =IF(E10="INACTIVE",0,D10+K10+L10+S10+T10+IF(V10="",0,V10)+IF(W10="",0,W10)) | Z10: =IF(E10="INACTIVE","_",IF(AND(G10>0,H10>0,H10<G10),"[!]น้ำ reset ","")&IF(AND(O10>0,P10>0,P10<O10),"[!]ไฟ reset ","")&IF(AND(F10="MANUAL",J10=""),"[X]units น้ำ ","")&IF(AND(N10="MANUAL",R10=""),"[X]units ไฟ ","")&IF(D10=0,"[!]ค่าเช่า=0","")) | AA10: =IF(C10<>"",C10,CONFIG!$B$6) | AB10: =IF(F10<>"",F10,IFERROR(VLOOKUP(AA10,RULES!$A:$C,3,0),CONFIG!$B$7)) | AC10: =IF(IFERROR(VLOOKUP(AA10,RULES!$A:$D,4,0),"")="",CONFIG!$B$10,VLOOKUP(AA10,RULES!$A:$D,4,0)) | AD10: =IF(IFERROR(VLOOKUP(AA10,RULES!$A:$E,5,0),"")="",CONFIG!$B$11,VLOOKUP(AA10,RULES!$A:$E,5,0)) | AE10: =IFERROR(VLOOKUP(AA10,RULES!$A:$F,6,0)*1,0) | AF10: =IFERROR(VLOOKUP(AA10,RULES!$A:$G,7,0)*1,0) | AG10: =IFERROR(VLOOKUP(AA10,RULES!$A:$H,8,0)*1,0) | AH10: =IFERROR(VLOOKUP(AA10,RULES!$A:$I,9,0)*1,0) | AI10: =IFERROR(VLOOKUP(AA10,RULES!$A:$J,10,0)*1,0) | AJ10: =IFERROR(IF(VLOOKUP(AA10,RULES!$A:$K,11,0)="",999999,VLOOKUP(AA10,RULES!$A:$K,11,0)*1),999999) | AK10: =IFERROR(VLOOKUP(AA10,RULES!$A:$L,12,0)*1,0) | AL10: =IFERROR(VLOOKUP(AA10,RULES!$A:$M,13,0),"NONE") | AM10: =IFERROR(VLOOKUP(AA10,RULES!$A:$N,14,0)*1,0) | AN10: =IFERROR(VLOOKUP(AA10,RULES!$A:$O,15,0)*1,0) | AO10: =IF(N10<>"",N10,IFERROR(VLOOKUP(AA10,RULES!$A:$P,16,0),CONFIG!$B$8)) | AP10: =IF(IFERROR(VLOOKUP(AA10,RULES!$A:$Q,17,0),"")="",CONFIG!$B$13,VLOOKUP(AA10,RULES!$A:$Q,17,0)) | AQ10: =IF(IFERROR(VLOOKUP(AA10,RULES!$A:$R,18,0),"")="",CONFIG!$B$14,VLOOKUP(AA10,RULES!$A:$R,18,0)) | AR10: =IFERROR(VLOOKUP(AA10,RULES!$A:$S,19,0)*1,0) | AS10: =IFERROR(VLOOKUP(AA10,RULES!$A:$T,20,0)*1,0) | AT10: =IFERROR(VLOOKUP(AA10,RULES!$A:$U,21,0)*1,0) | AU10: =IFERROR(VLOOKUP(AA10,RULES!$A:$V,22,0)*1,0) | AV10: =IFERROR(VLOOKUP(AA10,RULES!$A:$W,23,0)*1,0) | AW10: =IFERROR(IF(VLOOKUP(AA10,RULES!$A:$X,24,0)="",999999,VLOOKUP(AA10,RULES!$A:$X,24,0)*1),999999) | AX10: =IFERROR(VLOOKUP(AA10,RULES!$A:$Y,25,0)*1,0) | AY10: =IFERROR(VLOOKUP(AA10,RULES!$A:$Z,26,0),"NONE") | AZ10: =IFERROR(VLOOKUP(AA10,RULES!$A:$AA,27,0)*1,0) | BA10: =IFERROR(VLOOKUP(AA10,RULES!$A:$AB,28,0)*1,0)
A11: 798/8 | B11: ACC001 | C11: DEFAULT | E11: =IF(OR(D11="",D11=0),"INACTIVE","ACTIVE") | F11: NORMAL | I11: =IF(OR(E11="INACTIVE",H11=""),0,MAX(0,H11-G11)) | K11: =IF(OR(E11="INACTIVE",H11=""),0,IF(AB11="DISABLED",0,IF(AB11="FLAT",AE11,IF(AB11="MANUAL",IF(J11="",0,J11*AC11),IF(AB11="STEP",IF(I11<=AF11,I11*AG11,IF(I11<=AH11,AF11*AG11+(I11-AF11)*AI11,AF11*AG11+(AH11-AF11)*AI11+(I11-AH11)*AK11)),MAX(I11*AC11,AD11)))))) | L11: =IF(OR(E11="INACTIVE",H11=""),0,IF(AL11="NONE",0,IF(AL11="FLAT",AM11,IF(AL11="PER_UNIT",I11*AN11,IF(AL11="MANUAL",IF(M11="",0,M11),0))))) | N11: NORMAL | Q11: =IF(OR(E11="INACTIVE",P11=""),0,MAX(0,P11-O11)) | S11: =IF(OR(E11="INACTIVE",P11=""),0,IF(AO11="DISABLED",0,IF(AO11="FLAT",AR11,IF(AO11="MANUAL",IF(R11="",0,R11*AP11),IF(AO11="STEP",IF(Q11<=AS11,Q11*AT11,IF(Q11<=AU11,AS11*AT11+(Q11-AS11)*AV11,AS11*AT11+(AU11-AS11)*AV11+(Q11-AU11)*AX11)),MAX(Q11*AP11,AQ11)))))) | T11: =IF(OR(E11="INACTIVE",P11=""),0,IF(AY11="NONE",0,IF(AY11="FLAT",AZ11,IF(AY11="PER_UNIT",Q11*BA11,IF(AY11="MANUAL",IF(U11="",0,U11),0))))) | X11: =IF(E11="INACTIVE",0,D11+K11+L11+S11+T11+IF(V11="",0,V11)+IF(W11="",0,W11)) | Z11: =IF(E11="INACTIVE","_",IF(AND(G11>0,H11>0,H11<G11),"[!]น้ำ reset ","")&IF(AND(O11>0,P11>0,P11<O11),"[!]ไฟ reset ","")&IF(AND(F11="MANUAL",J11=""),"[X]units น้ำ ","")&IF(AND(N11="MANUAL",R11=""),"[X]units ไฟ ","")&IF(D11=0,"[!]ค่าเช่า=0","")) | AA11: =IF(C11<>"",C11,CONFIG!$B$6) | AB11: =IF(F11<>"",F11,IFERROR(VLOOKUP(AA11,RULES!$A:$C,3,0),CONFIG!$B$7)) | AC11: =IF(IFERROR(VLOOKUP(AA11,RULES!$A:$D,4,0),"")="",CONFIG!$B$10,VLOOKUP(AA11,RULES!$A:$D,4,0)) | AD11: =IF(IFERROR(VLOOKUP(AA11,RULES!$A:$E,5,0),"")="",CONFIG!$B$11,VLOOKUP(AA11,RULES!$A:$E,5,0)) | AE11: =IFERROR(VLOOKUP(AA11,RULES!$A:$F,6,0)*1,0) | AF11: =IFERROR(VLOOKUP(AA11,RULES!$A:$G,7,0)*1,0) | AG11: =IFERROR(VLOOKUP(AA11,RULES!$A:$H,8,0)*1,0) | AH11: =IFERROR(VLOOKUP(AA11,RULES!$A:$I,9,0)*1,0) | AI11: =IFERROR(VLOOKUP(AA11,RULES!$A:$J,10,0)*1,0) | AJ11: =IFERROR(IF(VLOOKUP(AA11,RULES!$A:$K,11,0)="",999999,VLOOKUP(AA11,RULES!$A:$K,11,0)*1),999999) | AK11: =IFERROR(VLOOKUP(AA11,RULES!$A:$L,12,0)*1,0) | AL11: =IFERROR(VLOOKUP(AA11,RULES!$A:$M,13,0),"NONE") | AM11: =IFERROR(VLOOKUP(AA11,RULES!$A:$N,14,0)*1,0) | AN11: =IFERROR(VLOOKUP(AA11,RULES!$A:$O,15,0)*1,0) | AO11: =IF(N11<>"",N11,IFERROR(VLOOKUP(AA11,RULES!$A:$P,16,0),CONFIG!$B$8)) | AP11: =IF(IFERROR(VLOOKUP(AA11,RULES!$A:$Q,17,0),"")="",CONFIG!$B$13,VLOOKUP(AA11,RULES!$A:$Q,17,0)) | AQ11: =IF(IFERROR(VLOOKUP(AA11,RULES!$A:$R,18,0),"")="",CONFIG!$B$14,VLOOKUP(AA11,RULES!$A:$R,18,0)) | AR11: =IFERROR(VLOOKUP(AA11,RULES!$A:$S,19,0)*1,0) | AS11: =IFERROR(VLOOKUP(AA11,RULES!$A:$T,20,0)*1,0) | AT11: =IFERROR(VLOOKUP(AA11,RULES!$A:$U,21,0)*1,0) | AU11: =IFERROR(VLOOKUP(AA11,RULES!$A:$V,22,0)*1,0) | AV11: =IFERROR(VLOOKUP(AA11,RULES!$A:$W,23,0)*1,0) | AW11: =IFERROR(IF(VLOOKUP(AA11,RULES!$A:$X,24,0)="",999999,VLOOKUP(AA11,RULES!$A:$X,24,0)*1),999999) | AX11: =IFERROR(VLOOKUP(AA11,RULES!$A:$Y,25,0)*1,0) | AY11: =IFERROR(VLOOKUP(AA11,RULES!$A:$Z,26,0),"NONE") | AZ11: =IFERROR(VLOOKUP(AA11,RULES!$A:$AA,27,0)*1,0) | BA11: =IFERROR(VLOOKUP(AA11,RULES!$A:$AB,28,0)*1,0)
A12: 798/9 | B12: ACC001 | C12: DEFAULT | E12: =IF(OR(D12="",D12=0),"INACTIVE","ACTIVE") | F12: NORMAL | I12: =IF(OR(E12="INACTIVE",H12=""),0,MAX(0,H12-G12)) | K12: =IF(OR(E12="INACTIVE",H12=""),0,IF(AB12="DISABLED",0,IF(AB12="FLAT",AE12,IF(AB12="MANUAL",IF(J12="",0,J12*AC12),IF(AB12="STEP",IF(I12<=AF12,I12*AG12,IF(I12<=AH12,AF12*AG12+(I12-AF12)*AI12,AF12*AG12+(AH12-AF12)*AI12+(I12-AH12)*AK12)),MAX(I12*AC12,AD12)))))) | L12: =IF(OR(E12="INACTIVE",H12=""),0,IF(AL12="NONE",0,IF(AL12="FLAT",AM12,IF(AL12="PER_UNIT",I12*AN12,IF(AL12="MANUAL",IF(M12="",0,M12),0))))) | N12: NORMAL | Q12: =IF(OR(E12="INACTIVE",P12=""),0,MAX(0,P12-O12)) | S12: =IF(OR(E12="INACTIVE",P12=""),0,IF(AO12="DISABLED",0,IF(AO12="FLAT",AR12,IF(AO12="MANUAL",IF(R12="",0,R12*AP12),IF(AO12="STEP",IF(Q12<=AS12,Q12*AT12,IF(Q12<=AU12,AS12*AT12+(Q12-AS12)*AV12,AS12*AT12+(AU12-AS12)*AV12+(Q12-AU12)*AX12)),MAX(Q12*AP12,AQ12)))))) | T12: =IF(OR(E12="INACTIVE",P12=""),0,IF(AY12="NONE",0,IF(AY12="FLAT",AZ12,IF(AY12="PER_UNIT",Q12*BA12,IF(AY12="MANUAL",IF(U12="",0,U12),0))))) | X12: =IF(E12="INACTIVE",0,D12+K12+L12+S12+T12+IF(V12="",0,V12)+IF(W12="",0,W12)) | Z12: =IF(E12="INACTIVE","_",IF(AND(G12>0,H12>0,H12<G12),"[!]น้ำ reset ","")&IF(AND(O12>0,P12>0,P12<O12),"[!]ไฟ reset ","")&IF(AND(F12="MANUAL",J12=""),"[X]units น้ำ ","")&IF(AND(N12="MANUAL",R12=""),"[X]units ไฟ ","")&IF(D12=0,"[!]ค่าเช่า=0","")) | AA12: =IF(C12<>"",C12,CONFIG!$B$6) | AB12: =IF(F12<>"",F12,IFERROR(VLOOKUP(AA12,RULES!$A:$C,3,0),CONFIG!$B$7)) | AC12: =IF(IFERROR(VLOOKUP(AA12,RULES!$A:$D,4,0),"")="",CONFIG!$B$10,VLOOKUP(AA12,RULES!$A:$D,4,0)) | AD12: =IF(IFERROR(VLOOKUP(AA12,RULES!$A:$E,5,0),"")="",CONFIG!$B$11,VLOOKUP(AA12,RULES!$A:$E,5,0)) | AE12: =IFERROR(VLOOKUP(AA12,RULES!$A:$F,6,0)*1,0) | AF12: =IFERROR(VLOOKUP(AA12,RULES!$A:$G,7,0)*1,0) | AG12: =IFERROR(VLOOKUP(AA12,RULES!$A:$H,8,0)*1,0) | AH12: =IFERROR(VLOOKUP(AA12,RULES!$A:$I,9,0)*1,0) | AI12: =IFERROR(VLOOKUP(AA12,RULES!$A:$J,10,0)*1,0) | AJ12: =IFERROR(IF(VLOOKUP(AA12,RULES!$A:$K,11,0)="",999999,VLOOKUP(AA12,RULES!$A:$K,11,0)*1),999999) | AK12: =IFERROR(VLOOKUP(AA12,RULES!$A:$L,12,0)*1,0) | AL12: =IFERROR(VLOOKUP(AA12,RULES!$A:$M,13,0),"NONE") | AM12: =IFERROR(VLOOKUP(AA12,RULES!$A:$N,14,0)*1,0) | AN12: =IFERROR(VLOOKUP(AA12,RULES!$A:$O,15,0)*1,0) | AO12: =IF(N12<>"",N12,IFERROR(VLOOKUP(AA12,RULES!$A:$P,16,0),CONFIG!$B$8)) | AP12: =IF(IFERROR(VLOOKUP(AA12,RULES!$A:$Q,17,0),"")="",CONFIG!$B$13,VLOOKUP(AA12,RULES!$A:$Q,17,0)) | AQ12: =IF(IFERROR(VLOOKUP(AA12,RULES!$A:$R,18,0),"")="",CONFIG!$B$14,VLOOKUP(AA12,RULES!$A:$R,18,0)) | AR12: =IFERROR(VLOOKUP(AA12,RULES!$A:$S,19,0)*1,0) | AS12: =IFERROR(VLOOKUP(AA12,RULES!$A:$T,20,0)*1,0) | AT12: =IFERROR(VLOOKUP(AA12,RULES!$A:$U,21,0)*1,0) | AU12: =IFERROR(VLOOKUP(AA12,RULES!$A:$V,22,0)*1,0) | AV12: =IFERROR(VLOOKUP(AA12,RULES!$A:$W,23,0)*1,0) | AW12: =IFERROR(IF(VLOOKUP(AA12,RULES!$A:$X,24,0)="",999999,VLOOKUP(AA12,RULES!$A:$X,24,0)*1),999999) | AX12: =IFERROR(VLOOKUP(AA12,RULES!$A:$Y,25,0)*1,0) | AY12: =IFERROR(VLOOKUP(AA12,RULES!$A:$Z,26,0),"NONE") | AZ12: =IFERROR(VLOOKUP(AA12,RULES!$A:$AA,27,0)*1,0) | BA12: =IFERROR(VLOOKUP(AA12,RULES!$A:$AB,28,0)*1,0)
A13: 798/10 | B13: ACC001 | C13: DEFAULT | E13: =IF(OR(D13="",D13=0),"INACTIVE","ACTIVE") | F13: NORMAL | I13: =IF(OR(E13="INACTIVE",H13=""),0,MAX(0,H13-G13)) | K13: =IF(OR(E13="INACTIVE",H13=""),0,IF(AB13="DISABLED",0,IF(AB13="FLAT",AE13,IF(AB13="MANUAL",IF(J13="",0,J13*AC13),IF(AB13="STEP",IF(I13<=AF13,I13*AG13,IF(I13<=AH13,AF13*AG13+(I13-AF13)*AI13,AF13*AG13+(AH13-AF13)*AI13+(I13-AH13)*AK13)),MAX(I13*AC13,AD13)))))) | L13: =IF(OR(E13="INACTIVE",H13=""),0,IF(AL13="NONE",0,IF(AL13="FLAT",AM13,IF(AL13="PER_UNIT",I13*AN13,IF(AL13="MANUAL",IF(M13="",0,M13),0))))) | N13: NORMAL | Q13: =IF(OR(E13="INACTIVE",P13=""),0,MAX(0,P13-O13)) | S13: =IF(OR(E13="INACTIVE",P13=""),0,IF(AO13="DISABLED",0,IF(AO13="FLAT",AR13,IF(AO13="MANUAL",IF(R13="",0,R13*AP13),IF(AO13="STEP",IF(Q13<=AS13,Q13*AT13,IF(Q13<=AU13,AS13*AT13+(Q13-AS13)*AV13,AS13*AT13+(AU13-AS13)*AV13+(Q13-AU13)*AX13)),MAX(Q13*AP13,AQ13)))))) | T13: =IF(OR(E13="INACTIVE",P13=""),0,IF(AY13="NONE",0,IF(AY13="FLAT",AZ13,IF(AY13="PER_UNIT",Q13*BA13,IF(AY13="MANUAL",IF(U13="",0,U13),0))))) | X13: =IF(E13="INACTIVE",0,D13+K13+L13+S13+T13+IF(V13="",0,V13)+IF(W13="",0,W13)) | Z13: =IF(E13="INACTIVE","_",IF(AND(G13>0,H13>0,H13<G13),"[!]น้ำ reset ","")&IF(AND(O13>0,P13>0,P13<O13),"[!]ไฟ reset ","")&IF(AND(F13="MANUAL",J13=""),"[X]units น้ำ ","")&IF(AND(N13="MANUAL",R13=""),"[X]units ไฟ ","")&IF(D13=0,"[!]ค่าเช่า=0","")) | AA13: =IF(C13<>"",C13,CONFIG!$B$6) | AB13: =IF(F13<>"",F13,IFERROR(VLOOKUP(AA13,RULES!$A:$C,3,0),CONFIG!$B$7)) | AC13: =IF(IFERROR(VLOOKUP(AA13,RULES!$A:$D,4,0),"")="",CONFIG!$B$10,VLOOKUP(AA13,RULES!$A:$D,4,0)) | AD13: =IF(IFERROR(VLOOKUP(AA13,RULES!$A:$E,5,0),"")="",CONFIG!$B$11,VLOOKUP(AA13,RULES!$A:$E,5,0)) | AE13: =IFERROR(VLOOKUP(AA13,RULES!$A:$F,6,0)*1,0) | AF13: =IFERROR(VLOOKUP(AA13,RULES!$A:$G,7,0)*1,0) | AG13: =IFERROR(VLOOKUP(AA13,RULES!$A:$H,8,0)*1,0) | AH13: =IFERROR(VLOOKUP(AA13,RULES!$A:$I,9,0)*1,0) | AI13: =IFERROR(VLOOKUP(AA13,RULES!$A:$J,10,0)*1,0) | AJ13: =IFERROR(IF(VLOOKUP(AA13,RULES!$A:$K,11,0)="",999999,VLOOKUP(AA13,RULES!$A:$K,11,0)*1),999999) | AK13: =IFERROR(VLOOKUP(AA13,RULES!$A:$L,12,0)*1,0) | AL13: =IFERROR(VLOOKUP(AA13,RULES!$A:$M,13,0),"NONE") | AM13: =IFERROR(VLOOKUP(AA13,RULES!$A:$N,14,0)*1,0) | AN13: =IFERROR(VLOOKUP(AA13,RULES!$A:$O,15,0)*1,0) | AO13: =IF(N13<>"",N13,IFERROR(VLOOKUP(AA13,RULES!$A:$P,16,0),CONFIG!$B$8)) | AP13: =IF(IFERROR(VLOOKUP(AA13,RULES!$A:$Q,17,0),"")="",CONFIG!$B$13,VLOOKUP(AA13,RULES!$A:$Q,17,0)) | AQ13: =IF(IFERROR(VLOOKUP(AA13,RULES!$A:$R,18,0),"")="",CONFIG!$B$14,VLOOKUP(AA13,RULES!$A:$R,18,0)) | AR13: =IFERROR(VLOOKUP(AA13,RULES!$A:$S,19,0)*1,0) | AS13: =IFERROR(VLOOKUP(AA13,RULES!$A:$T,20,0)*1,0) | AT13: =IFERROR(VLOOKUP(AA13,RULES!$A:$U,21,0)*1,0) | AU13: =IFERROR(VLOOKUP(AA13,RULES!$A:$V,22,0)*1,0) | AV13: =IFERROR(VLOOKUP(AA13,RULES!$A:$W,23,0)*1,0) | AW13: =IFERROR(IF(VLOOKUP(AA13,RULES!$A:$X,24,0)="",999999,VLOOKUP(AA13,RULES!$A:$X,24,0)*1),999999) | AX13: =IFERROR(VLOOKUP(AA13,RULES!$A:$Y,25,0)*1,0) | AY13: =IFERROR(VLOOKUP(AA13,RULES!$A:$Z,26,0),"NONE") | AZ13: =IFERROR(VLOOKUP(AA13,RULES!$A:$AA,27,0)*1,0) | BA13: =IFERROR(VLOOKUP(AA13,RULES!$A:$AB,28,0)*1,0)
A14: 798/11 | B14: ACC001 | C14: DEFAULT | E14: =IF(OR(D14="",D14=0),"INACTIVE","ACTIVE") | F14: NORMAL | I14: =IF(OR(E14="INACTIVE",H14=""),0,MAX(0,H14-G14)) | K14: =IF(OR(E14="INACTIVE",H14=""),0,IF(AB14="DISABLED",0,IF(AB14="FLAT",AE14,IF(AB14="MANUAL",IF(J14="",0,J14*AC14),IF(AB14="STEP",IF(I14<=AF14,I14*AG14,IF(I14<=AH14,AF14*AG14+(I14-AF14)*AI14,AF14*AG14+(AH14-AF14)*AI14+(I14-AH14)*AK14)),MAX(I14*AC14,AD14)))))) | L14: =IF(OR(E14="INACTIVE",H14=""),0,IF(AL14="NONE",0,IF(AL14="FLAT",AM14,IF(AL14="PER_UNIT",I14*AN14,IF(AL14="MANUAL",IF(M14="",0,M14),0))))) | N14: NORMAL | Q14: =IF(OR(E14="INACTIVE",P14=""),0,MAX(0,P14-O14)) | S14: =IF(OR(E14="INACTIVE",P14=""),0,IF(AO14="DISABLED",0,IF(AO14="FLAT",AR14,IF(AO14="MANUAL",IF(R14="",0,R14*AP14),IF(AO14="STEP",IF(Q14<=AS14,Q14*AT14,IF(Q14<=AU14,AS14*AT14+(Q14-AS14)*AV14,AS14*AT14+(AU14-AS14)*AV14+(Q14-AU14)*AX14)),MAX(Q14*AP14,AQ14)))))) | T14: =IF(OR(E14="INACTIVE",P14=""),0,IF(AY14="NONE",0,IF(AY14="FLAT",AZ14,IF(AY14="PER_UNIT",Q14*BA14,IF(AY14="MANUAL",IF(U14="",0,U14),0))))) | X14: =IF(E14="INACTIVE",0,D14+K14+L14+S14+T14+IF(V14="",0,V14)+IF(W14="",0,W14)) | Z14: =IF(E14="INACTIVE","_",IF(AND(G14>0,H14>0,H14<G14),"[!]น้ำ reset ","")&IF(AND(O14>0,P14>0,P14<O14),"[!]ไฟ reset ","")&IF(AND(F14="MANUAL",J14=""),"[X]units น้ำ ","")&IF(AND(N14="MANUAL",R14=""),"[X]units ไฟ ","")&IF(D14=0,"[!]ค่าเช่า=0","")) | AA14: =IF(C14<>"",C14,CONFIG!$B$6) | AB14: =IF(F14<>"",F14,IFERROR(VLOOKUP(AA14,RULES!$A:$C,3,0),CONFIG!$B$7)) | AC14: =IF(IFERROR(VLOOKUP(AA14,RULES!$A:$D,4,0),"")="",CONFIG!$B$10,VLOOKUP(AA14,RULES!$A:$D,4,0)) | AD14: =IF(IFERROR(VLOOKUP(AA14,RULES!$A:$E,5,0),"")="",CONFIG!$B$11,VLOOKUP(AA14,RULES!$A:$E,5,0)) | AE14: =IFERROR(VLOOKUP(AA14,RULES!$A:$F,6,0)*1,0) | AF14: =IFERROR(VLOOKUP(AA14,RULES!$A:$G,7,0)*1,0) | AG14: =IFERROR(VLOOKUP(AA14,RULES!$A:$H,8,0)*1,0) | AH14: =IFERROR(VLOOKUP(AA14,RULES!$A:$I,9,0)*1,0) | AI14: =IFERROR(VLOOKUP(AA14,RULES!$A:$J,10,0)*1,0) | AJ14: =IFERROR(IF(VLOOKUP(AA14,RULES!$A:$K,11,0)="",999999,VLOOKUP(AA14,RULES!$A:$K,11,0)*1),999999) | AK14: =IFERROR(VLOOKUP(AA14,RULES!$A:$L,12,0)*1,0) | AL14: =IFERROR(VLOOKUP(AA14,RULES!$A:$M,13,0),"NONE") | AM14: =IFERROR(VLOOKUP(AA14,RULES!$A:$N,14,0)*1,0) | AN14: =IFERROR(VLOOKUP(AA14,RULES!$A:$O,15,0)*1,0) | AO14: =IF(N14<>"",N14,IFERROR(VLOOKUP(AA14,RULES!$A:$P,16,0),CONFIG!$B$8)) | AP14: =IF(IFERROR(VLOOKUP(AA14,RULES!$A:$Q,17,0),"")="",CONFIG!$B$13,VLOOKUP(AA14,RULES!$A:$Q,17,0)) | AQ14: =IF(IFERROR(VLOOKUP(AA14,RULES!$A:$R,18,0),"")="",CONFIG!$B$14,VLOOKUP(AA14,RULES!$A:$R,18,0)) | AR14: =IFERROR(VLOOKUP(AA14,RULES!$A:$S,19,0)*1,0) | AS14: =IFERROR(VLOOKUP(AA14,RULES!$A:$T,20,0)*1,0) | AT14: =IFERROR(VLOOKUP(AA14,RULES!$A:$U,21,0)*1,0) | AU14: =IFERROR(VLOOKUP(AA14,RULES!$A:$V,22,0)*1,0) | AV14: =IFERROR(VLOOKUP(AA14,RULES!$A:$W,23,0)*1,0) | AW14: =IFERROR(IF(VLOOKUP(AA14,RULES!$A:$X,24,0)="",999999,VLOOKUP(AA14,RULES!$A:$X,24,0)*1),999999) | AX14: =IFERROR(VLOOKUP(AA14,RULES!$A:$Y,25,0)*1,0) | AY14: =IFERROR(VLOOKUP(AA14,RULES!$A:$Z,26,0),"NONE") | AZ14: =IFERROR(VLOOKUP(AA14,RULES!$A:$AA,27,0)*1,0) | BA14: =IFERROR(VLOOKUP(AA14,RULES!$A:$AB,28,0)*1,0)
A15: 798/12 | B15: ACC001 | C15: DEFAULT | E15: =IF(OR(D15="",D15=0),"INACTIVE","ACTIVE") | F15: NORMAL | I15: =IF(OR(E15="INACTIVE",H15=""),0,MAX(0,H15-G15)) | K15: =IF(OR(E15="INACTIVE",H15=""),0,IF(AB15="DISABLED",0,IF(AB15="FLAT",AE15,IF(AB15="MANUAL",IF(J15="",0,J15*AC15),IF(AB15="STEP",IF(I15<=AF15,I15*AG15,IF(I15<=AH15,AF15*AG15+(I15-AF15)*AI15,AF15*AG15+(AH15-AF15)*AI15+(I15-AH15)*AK15)),MAX(I15*AC15,AD15)))))) | L15: =IF(OR(E15="INACTIVE",H15=""),0,IF(AL15="NONE",0,IF(AL15="FLAT",AM15,IF(AL15="PER_UNIT",I15*AN15,IF(AL15="MANUAL",IF(M15="",0,M15),0))))) | N15: NORMAL | Q15: =IF(OR(E15="INACTIVE",P15=""),0,MAX(0,P15-O15)) | S15: =IF(OR(E15="INACTIVE",P15=""),0,IF(AO15="DISABLED",0,IF(AO15="FLAT",AR15,IF(AO15="MANUAL",IF(R15="",0,R15*AP15),IF(AO15="STEP",IF(Q15<=AS15,Q15*AT15,IF(Q15<=AU15,AS15*AT15+(Q15-AS15)*AV15,AS15*AT15+(AU15-AS15)*AV15+(Q15-AU15)*AX15)),MAX(Q15*AP15,AQ15)))))) | T15: =IF(OR(E15="INACTIVE",P15=""),0,IF(AY15="NONE",0,IF(AY15="FLAT",AZ15,IF(AY15="PER_UNIT",Q15*BA15,IF(AY15="MANUAL",IF(U15="",0,U15),0))))) | X15: =IF(E15="INACTIVE",0,D15+K15+L15+S15+T15+IF(V15="",0,V15)+IF(W15="",0,W15)) | Z15: =IF(E15="INACTIVE","_",IF(AND(G15>0,H15>0,H15<G15),"[!]น้ำ reset ","")&IF(AND(O15>0,P15>0,P15<O15),"[!]ไฟ reset ","")&IF(AND(F15="MANUAL",J15=""),"[X]units น้ำ ","")&IF(AND(N15="MANUAL",R15=""),"[X]units ไฟ ","")&IF(D15=0,"[!]ค่าเช่า=0","")) | AA15: =IF(C15<>"",C15,CONFIG!$B$6) | AB15: =IF(F15<>"",F15,IFERROR(VLOOKUP(AA15,RULES!$A:$C,3,0),CONFIG!$B$7)) | AC15: =IF(IFERROR(VLOOKUP(AA15,RULES!$A:$D,4,0),"")="",CONFIG!$B$10,VLOOKUP(AA15,RULES!$A:$D,4,0)) | AD15: =IF(IFERROR(VLOOKUP(AA15,RULES!$A:$E,5,0),"")="",CONFIG!$B$11,VLOOKUP(AA15,RULES!$A:$E,5,0)) | AE15: =IFERROR(VLOOKUP(AA15,RULES!$A:$F,6,0)*1,0) | AF15: =IFERROR(VLOOKUP(AA15,RULES!$A:$G,7,0)*1,0) | AG15: =IFERROR(VLOOKUP(AA15,RULES!$A:$H,8,0)*1,0) | AH15: =IFERROR(VLOOKUP(AA15,RULES!$A:$I,9,0)*1,0) | AI15: =IFERROR(VLOOKUP(AA15,RULES!$A:$J,10,0)*1,0) | AJ15: =IFERROR(IF(VLOOKUP(AA15,RULES!$A:$K,11,0)="",999999,VLOOKUP(AA15,RULES!$A:$K,11,0)*1),999999) | AK15: =IFERROR(VLOOKUP(AA15,RULES!$A:$L,12,0)*1,0) | AL15: =IFERROR(VLOOKUP(AA15,RULES!$A:$M,13,0),"NONE") | AM15: =IFERROR(VLOOKUP(AA15,RULES!$A:$N,14,0)*1,0) | AN15: =IFERROR(VLOOKUP(AA15,RULES!$A:$O,15,0)*1,0) | AO15: =IF(N15<>"",N15,IFERROR(VLOOKUP(AA15,RULES!$A:$P,16,0),CONFIG!$B$8)) | AP15: =IF(IFERROR(VLOOKUP(AA15,RULES!$A:$Q,17,0),"")="",CONFIG!$B$13,VLOOKUP(AA15,RULES!$A:$Q,17,0)) | AQ15: =IF(IFERROR(VLOOKUP(AA15,RULES!$A:$R,18,0),"")="",CONFIG!$B$14,VLOOKUP(AA15,RULES!$A:$R,18,0)) | AR15: =IFERROR(VLOOKUP(AA15,RULES!$A:$S,19,0)*1,0) | AS15: =IFERROR(VLOOKUP(AA15,RULES!$A:$T,20,0)*1,0) | AT15: =IFERROR(VLOOKUP(AA15,RULES!$A:$U,21,0)*1,0) | AU15: =IFERROR(VLOOKUP(AA15,RULES!$A:$V,22,0)*1,0) | AV15: =IFERROR(VLOOKUP(AA15,RULES!$A:$W,23,0)*1,0) | AW15: =IFERROR(IF(VLOOKUP(AA15,RULES!$A:$X,24,0)="",999999,VLOOKUP(AA15,RULES!$A:$X,24,0)*1),999999) | AX15: =IFERROR(VLOOKUP(AA15,RULES!$A:$Y,25,0)*1,0) | AY15: =IFERROR(VLOOKUP(AA15,RULES!$A:$Z,26,0),"NONE") | AZ15: =IFERROR(VLOOKUP(AA15,RULES!$A:$AA,27,0)*1,0) | BA15: =IFERROR(VLOOKUP(AA15,RULES!$A:$AB,28,0)*1,0)
... A18: 798/15 | B18: ACC001 | C18: DEFAULT | E18: =IF(OR(D18="",D18=0),"INACTIVE","ACTIVE") | F18: NORMAL | I18: =IF(OR(E18="INACTIVE",H18=""),0,MAX(0,H18-G18)) | K18: =IF(OR(E18="INACTIVE",H18=""),0,IF(AB18="DISABLED",0,IF(AB18="FLAT",AE18,IF(AB18="MANUAL",IF(J18="",0,J18*AC18),IF(AB18="STEP",IF(I18<=AF18,I18*AG18,IF(I18<=AH18,AF18*AG18+(I18-AF18)*AI18,AF18*AG18+(AH18-AF18)*AI18+(I18-AH18)*AK18)),MAX(I18*AC18,AD18)))))) | L18: =IF(OR(E18="INACTIVE",H18=""),0,IF(AL18="NONE",0,IF(AL18="FLAT",AM18,IF(AL18="PER_UNIT",I18*AN18,IF(AL18="MANUAL",IF(M18="",0,M18),0))))) | N18: NORMAL | Q18: =IF(OR(E18="INACTIVE",P18=""),0,MAX(0,P18-O18)) | S18: =IF(OR(E18="INACTIVE",P18=""),0,IF(AO18="DISABLED",0,IF(AO18="FLAT",AR18,IF(AO18="MANUAL",IF(R18="",0,R18*AP18),IF(AO18="STEP",IF(Q18<=AS18,Q18*AT18,IF(Q18<=AU18,AS18*AT18+(Q18-AS18)*AV18,AS18*AT18+(AU18-AS18)*AV18+(Q18-AU18)*AX18)),MAX(Q18*AP18,AQ18)))))) | T18: =IF(OR(E18="INACTIVE",P18=""),0,IF(AY18="NONE",0,IF(AY18="FLAT",AZ18,IF(AY18="PER_UNIT",Q18*BA18,IF(AY18="MANUAL",IF(U18="",0,U18),0))))) | X18: =IF(E18="INACTIVE",0,D18+K18+L18+S18+T18+IF(V18="",0,V18)+IF(W18="",0,W18)) | Z18: =IF(E18="INACTIVE","_",IF(AND(G18>0,H18>0,H18<G18),"[!]น้ำ reset ","")&IF(AND(O18>0,P18>0,P18<O18),"[!]ไฟ reset ","")&IF(AND(F18="MANUAL",J18=""),"[X]units น้ำ ","")&IF(AND(N18="MANUAL",R18=""),"[X]units ไฟ ","")&IF(D18=0,"[!]ค่าเช่า=0","")) | AA18: =IF(C18<>"",C18,CONFIG!$B$6) | AB18: =IF(F18<>"",F18,IFERROR(VLOOKUP(AA18,RULES!$A:$C,3,0),CONFIG!$B$7)) | AC18: =IF(IFERROR(VLOOKUP(AA18,RULES!$A:$D,4,0),"")="",CONFIG!$B$10,VLOOKUP(AA18,RULES!$A:$D,4,0)) | AD18: =IF(IFERROR(VLOOKUP(AA18,RULES!$A:$E,5,0),"")="",CONFIG!$B$11,VLOOKUP(AA18,RULES!$A:$E,5,0)) | AE18: =IFERROR(VLOOKUP(AA18,RULES!$A:$F,6,0)*1,0) | AF18: =IFERROR(VLOOKUP(AA18,RULES!$A:$G,7,0)*1,0) | AG18: =IFERROR(VLOOKUP(AA18,RULES!$A:$H,8,0)*1,0) | AH18: =IFERROR(VLOOKUP(AA18,RULES!$A:$I,9,0)*1,0) | AI18: =IFERROR(VLOOKUP(AA18,RULES!$A:$J,10,0)*1,0) | AJ18: =IFERROR(IF(VLOOKUP(AA18,RULES!$A:$K,11,0)="",999999,VLOOKUP(AA18,RULES!$A:$K,11,0)*1),999999) | AK18: =IFERROR(VLOOKUP(AA18,RULES!$A:$L,12,0)*1,0) | AL18: =IFERROR(VLOOKUP(AA18,RULES!$A:$M,13,0),"NONE") | AM18: =IFERROR(VLOOKUP(AA18,RULES!$A:$N,14,0)*1,0) | AN18: =IFERROR(VLOOKUP(AA18,RULES!$A:$O,15,0)*1,0) | AO18: =IF(N18<>"",N18,IFERROR(VLOOKUP(AA18,RULES!$A:$P,16,0),CONFIG!$B$8)) | AP18: =IF(IFERROR(VLOOKUP(AA18,RULES!$A:$Q,17,0),"")="",CONFIG!$B$13,VLOOKUP(AA18,RULES!$A:$Q,17,0)) | AQ18: =IF(IFERROR(VLOOKUP(AA18,RULES!$A:$R,18,0),"")="",CONFIG!$B$14,VLOOKUP(AA18,RULES!$A:$R,18,0)) | AR18: =IFERROR(VLOOKUP(AA18,RULES!$A:$S,19,0)*1,0) | AS18: =IFERROR(VLOOKUP(AA18,RULES!$A:$T,20,0)*1,0) | AT18: =IFERROR(VLOOKUP(AA18,RULES!$A:$U,21,0)*1,0) | AU18: =IFERROR(VLOOKUP(AA18,RULES!$A:$V,22,0)*1,0) | AV18: =IFERROR(VLOOKUP(AA18,RULES!$A:$W,23,0)*1,0) | AW18: =IFERROR(IF(VLOOKUP(AA18,RULES!$A:$X,24,0)="",999999,VLOOKUP(AA18,RULES!$A:$X,24,0)*1),999999) | AX18: =IFERROR(VLOOKUP(AA18,RULES!$A:$Y,25,0)*1,0) | AY18: =IFERROR(VLOOKUP(AA18,RULES!$A:$Z,26,0),"NONE") | AZ18: =IFERROR(VLOOKUP(AA18,RULES!$A:$AA,27,0)*1,0) | BA18: =IFERROR(VLOOKUP(AA18,RULES!$A:$AB,28,0)*1,0)
C19: DEFAULT | E19: =IF(OR(D19="",D19=0),"INACTIVE","ACTIVE") | F19: NORMAL | I19: =IF(OR(E19="INACTIVE",H19=""),0,MAX(0,H19-G19)) | K19: =IF(OR(E19="INACTIVE",H19=""),0,IF(AB19="DISABLED",0,IF(AB19="FLAT",AE19,IF(AB19="MANUAL",IF(J19="",0,J19*AC19),IF(AB19="STEP",IF(I19<=AF19,I19*AG19,IF(I19<=AH19,AF19*AG19+(I19-AF19)*AI19,AF19*AG19+(AH19-AF19)*AI19+(I19-AH19)*AK19)),MAX(I19*AC19,AD19)))))) | L19: =IF(OR(E19="INACTIVE",H19=""),0,IF(AL19="NONE",0,IF(AL19="FLAT",AM19,IF(AL19="PER_UNIT",I19*AN19,IF(AL19="MANUAL",IF(M19="",0,M19),0))))) | N19: NORMAL | Q19: =IF(OR(E19="INACTIVE",P19=""),0,MAX(0,P19-O19)) | S19: =IF(OR(E19="INACTIVE",P19=""),0,IF(AO19="DISABLED",0,IF(AO19="FLAT",AR19,IF(AO19="MANUAL",IF(R19="",0,R19*AP19),IF(AO19="STEP",IF(Q19<=AS19,Q19*AT19,IF(Q19<=AU19,AS19*AT19+(Q19-AS19)*AV19,AS19*AT19+(AU19-AS19)*AV19+(Q19-AU19)*AX19)),MAX(Q19*AP19,AQ19)))))) | T19: =IF(OR(E19="INACTIVE",P19=""),0,IF(AY19="NONE",0,IF(AY19="FLAT",AZ19,IF(AY19="PER_UNIT",Q19*BA19,IF(AY19="MANUAL",IF(U19="",0,U19),0))))) | X19: =IF(E19="INACTIVE",0,D19+K19+L19+S19+T19+IF(V19="",0,V19)+IF(W19="",0,W19)) | Z19: =IF(E19="INACTIVE","_",IF(AND(G19>0,H19>0,H19<G19),"[!]น้ำ reset ","")&IF(AND(O19>0,P19>0,P19<O19),"[!]ไฟ reset ","")&IF(AND(F19="MANUAL",J19=""),"[X]units น้ำ ","")&IF(AND(N19="MANUAL",R19=""),"[X]units ไฟ ","")&IF(D19=0,"[!]ค่าเช่า=0","")) | AA19: =IF(C19<>"",C19,CONFIG!$B$6) | AB19: =IF(F19<>"",F19,IFERROR(VLOOKUP(AA19,RULES!$A:$C,3,0),CONFIG!$B$7)) | AC19: =IF(IFERROR(VLOOKUP(AA19,RULES!$A:$D,4,0),"")="",CONFIG!$B$10,VLOOKUP(AA19,RULES!$A:$D,4,0)) | AD19: =IF(IFERROR(VLOOKUP(AA19,RULES!$A:$E,5,0),"")="",CONFIG!$B$11,VLOOKUP(AA19,RULES!$A:$E,5,0)) | AE19: =IFERROR(VLOOKUP(AA19,RULES!$A:$F,6,0)*1,0) | AF19: =IFERROR(VLOOKUP(AA19,RULES!$A:$G,7,0)*1,0) | AG19: =IFERROR(VLOOKUP(AA19,RULES!$A:$H,8,0)*1,0) | AH19: =IFERROR(VLOOKUP(AA19,RULES!$A:$I,9,0)*1,0) | AI19: =IFERROR(VLOOKUP(AA19,RULES!$A:$J,10,0)*1,0) | AJ19: =IFERROR(IF(VLOOKUP(AA19,RULES!$A:$K,11,0)="",999999,VLOOKUP(AA19,RULES!$A:$K,11,0)*1),999999) | AK19: =IFERROR(VLOOKUP(AA19,RULES!$A:$L,12,0)*1,0) | AL19: =IFERROR(VLOOKUP(AA19,RULES!$A:$M,13,0),"NONE") | AM19: =IFERROR(VLOOKUP(AA19,RULES!$A:$N,14,0)*1,0) | AN19: =IFERROR(VLOOKUP(AA19,RULES!$A:$O,15,0)*1,0) | AO19: =IF(N19<>"",N19,IFERROR(VLOOKUP(AA19,RULES!$A:$P,16,0),CONFIG!$B$8)) | AP19: =IF(IFERROR(VLOOKUP(AA19,RULES!$A:$Q,17,0),"")="",CONFIG!$B$13,VLOOKUP(AA19,RULES!$A:$Q,17,0)) | AQ19: =IF(IFERROR(VLOOKUP(AA19,RULES!$A:$R,18,0),"")="",CONFIG!$B$14,VLOOKUP(AA19,RULES!$A:$R,18,0)) | AR19: =IFERROR(VLOOKUP(AA19,RULES!$A:$S,19,0)*1,0) | AS19: =IFERROR(VLOOKUP(AA19,RULES!$A:$T,20,0)*1,0) | AT19: =IFERROR(VLOOKUP(AA19,RULES!$A:$U,21,0)*1,0) | AU19: =IFERROR(VLOOKUP(AA19,RULES!$A:$V,22,0)*1,0) | AV19: =IFERROR(VLOOKUP(AA19,RULES!$A:$W,23,0)*1,0) | AW19: =IFERROR(IF(VLOOKUP(AA19,RULES!$A:$X,24,0)="",999999,VLOOKUP(AA19,RULES!$A:$X,24,0)*1),999999) | AX19: =IFERROR(VLOOKUP(AA19,RULES!$A:$Y,25,0)*1,0) | AY19: =IFERROR(VLOOKUP(AA19,RULES!$A:$Z,26,0),"NONE") | AZ19: =IFERROR(VLOOKUP(AA19,RULES!$A:$AA,27,0)*1,0) | BA19: =IFERROR(VLOOKUP(AA19,RULES!$A:$AB,28,0)*1,0)
B20: ACC001 | C20: DEFAULT | E20: =IF(OR(D20="",D20=0),"INACTIVE","ACTIVE") | F20: NORMAL | I20: =IF(OR(E20="INACTIVE",H20=""),0,MAX(0,H20-G20)) | K20: =IF(OR(E20="INACTIVE",H20=""),0,IF(AB20="DISABLED",0,IF(AB20="FLAT",AE20,IF(AB20="MANUAL",IF(J20="",0,J20*AC20),IF(AB20="STEP",IF(I20<=AF20,I20*AG20,IF(I20<=AH20,AF20*AG20+(I20-AF20)*AI20,AF20*AG20+(AH20-AF20)*AI20+(I20-AH20)*AK20)),MAX(I20*AC20,AD20)))))) | L20: =IF(OR(E20="INACTIVE",H20=""),0,IF(AL20="NONE",0,IF(AL20="FLAT",AM20,IF(AL20="PER_UNIT",I20*AN20,IF(AL20="MANUAL",IF(M20="",0,M20),0))))) | N20: NORMAL | Q20: =IF(OR(E20="INACTIVE",P20=""),0,MAX(0,P20-O20)) | S20: =IF(OR(E20="INACTIVE",P20=""),0,IF(AO20="DISABLED",0,IF(AO20="FLAT",AR20,IF(AO20="MANUAL",IF(R20="",0,R20*AP20),IF(AO20="STEP",IF(Q20<=AS20,Q20*AT20,IF(Q20<=AU20,AS20*AT20+(Q20-AS20)*AV20,AS20*AT20+(AU20-AS20)*AV20+(Q20-AU20)*AX20)),MAX(Q20*AP20,AQ20)))))) | T20: =IF(OR(E20="INACTIVE",P20=""),0,IF(AY20="NONE",0,IF(AY20="FLAT",AZ20,IF(AY20="PER_UNIT",Q20*BA20,IF(AY20="MANUAL",IF(U20="",0,U20),0))))) | X20: =IF(E20="INACTIVE",0,D20+K20+L20+S20+T20+IF(V20="",0,V20)+IF(W20="",0,W20)) | Z20: =IF(E20="INACTIVE","_",IF(AND(G20>0,H20>0,H20<G20),"[!]น้ำ reset ","")&IF(AND(O20>0,P20>0,P20<O20),"[!]ไฟ reset ","")&IF(AND(F20="MANUAL",J20=""),"[X]units น้ำ ","")&IF(AND(N20="MANUAL",R20=""),"[X]units ไฟ ","")&IF(D20=0,"[!]ค่าเช่า=0","")) | AA20: =IF(C20<>"",C20,CONFIG!$B$6) | AB20: =IF(F20<>"",F20,IFERROR(VLOOKUP(AA20,RULES!$A:$C,3,0),CONFIG!$B$7)) | AC20: =IF(IFERROR(VLOOKUP(AA20,RULES!$A:$D,4,0),"")="",CONFIG!$B$10,VLOOKUP(AA20,RULES!$A:$D,4,0)) | AD20: =IF(IFERROR(VLOOKUP(AA20,RULES!$A:$E,5,0),"")="",CONFIG!$B$11,VLOOKUP(AA20,RULES!$A:$E,5,0)) | AE20: =IFERROR(VLOOKUP(AA20,RULES!$A:$F,6,0)*1,0) | AF20: =IFERROR(VLOOKUP(AA20,RULES!$A:$G,7,0)*1,0) | AG20: =IFERROR(VLOOKUP(AA20,RULES!$A:$H,8,0)*1,0) | AH20: =IFERROR(VLOOKUP(AA20,RULES!$A:$I,9,0)*1,0) | AI20: =IFERROR(VLOOKUP(AA20,RULES!$A:$J,10,0)*1,0) | AJ20: =IFERROR(IF(VLOOKUP(AA20,RULES!$A:$K,11,0)="",999999,VLOOKUP(AA20,RULES!$A:$K,11,0)*1),999999) | AK20: =IFERROR(VLOOKUP(AA20,RULES!$A:$L,12,0)*1,0) | AL20: =IFERROR(VLOOKUP(AA20,RULES!$A:$M,13,0),"NONE") | AM20: =IFERROR(VLOOKUP(AA20,RULES!$A:$N,14,0)*1,0) | AN20: =IFERROR(VLOOKUP(AA20,RULES!$A:$O,15,0)*1,0) | AO20: =IF(N20<>"",N20,IFERROR(VLOOKUP(AA20,RULES!$A:$P,16,0),CONFIG!$B$8)) | AP20: =IF(IFERROR(VLOOKUP(AA20,RULES!$A:$Q,17,0),"")="",CONFIG!$B$13,VLOOKUP(AA20,RULES!$A:$Q,17,0)) | AQ20: =IF(IFERROR(VLOOKUP(AA20,RULES!$A:$R,18,0),"")="",CONFIG!$B$14,VLOOKUP(AA20,RULES!$A:$R,18,0)) | AR20: =IFERROR(VLOOKUP(AA20,RULES!$A:$S,19,0)*1,0) | AS20: =IFERROR(VLOOKUP(AA20,RULES!$A:$T,20,0)*1,0) | AT20: =IFERROR(VLOOKUP(AA20,RULES!$A:$U,21,0)*1,0) | AU20: =IFERROR(VLOOKUP(AA20,RULES!$A:$V,22,0)*1,0) | AV20: =IFERROR(VLOOKUP(AA20,RULES!$A:$W,23,0)*1,0) | AW20: =IFERROR(IF(VLOOKUP(AA20,RULES!$A:$X,24,0)="",999999,VLOOKUP(AA20,RULES!$A:$X,24,0)*1),999999) | AX20: =IFERROR(VLOOKUP(AA20,RULES!$A:$Y,25,0)*1,0) | AY20: =IFERROR(VLOOKUP(AA20,RULES!$A:$Z,26,0),"NONE") | AZ20: =IFERROR(VLOOKUP(AA20,RULES!$A:$AA,27,0)*1,0) | BA20: =IFERROR(VLOOKUP(AA20,RULES!$A:$AB,28,0)*1,0)
B21: ACC001 | C21: DEFAULT | E21: =IF(OR(D21="",D21=0),"INACTIVE","ACTIVE") | F21: NORMAL | I21: =IF(OR(E21="INACTIVE",H21=""),0,MAX(0,H21-G21)) | K21: =IF(OR(E21="INACTIVE",H21=""),0,IF(AB21="DISABLED",0,IF(AB21="FLAT",AE21,IF(AB21="MANUAL",IF(J21="",0,J21*AC21),IF(AB21="STEP",IF(I21<=AF21,I21*AG21,IF(I21<=AH21,AF21*AG21+(I21-AF21)*AI21,AF21*AG21+(AH21-AF21)*AI21+(I21-AH21)*AK21)),MAX(I21*AC21,AD21)))))) | L21: =IF(OR(E21="INACTIVE",H21=""),0,IF(AL21="NONE",0,IF(AL21="FLAT",AM21,IF(AL21="PER_UNIT",I21*AN21,IF(AL21="MANUAL",IF(M21="",0,M21),0))))) | N21: NORMAL | Q21: =IF(OR(E21="INACTIVE",P21=""),0,MAX(0,P21-O21)) | S21: =IF(OR(E21="INACTIVE",P21=""),0,IF(AO21="DISABLED",0,IF(AO21="FLAT",AR21,IF(AO21="MANUAL",IF(R21="",0,R21*AP21),IF(AO21="STEP",IF(Q21<=AS21,Q21*AT21,IF(Q21<=AU21,AS21*AT21+(Q21-AS21)*AV21,AS21*AT21+(AU21-AS21)*AV21+(Q21-AU21)*AX21)),MAX(Q21*AP21,AQ21)))))) | T21: =IF(OR(E21="INACTIVE",P21=""),0,IF(AY21="NONE",0,IF(AY21="FLAT",AZ21,IF(AY21="PER_UNIT",Q21*BA21,IF(AY21="MANUAL",IF(U21="",0,U21),0))))) | X21: =IF(E21="INACTIVE",0,D21+K21+L21+S21+T21+IF(V21="",0,V21)+IF(W21="",0,W21)) | Z21: =IF(E21="INACTIVE","_",IF(AND(G21>0,H21>0,H21<G21),"[!]น้ำ reset ","")&IF(AND(O21>0,P21>0,P21<O21),"[!]ไฟ reset ","")&IF(AND(F21="MANUAL",J21=""),"[X]units น้ำ ","")&IF(AND(N21="MANUAL",R21=""),"[X]units ไฟ ","")&IF(D21=0,"[!]ค่าเช่า=0","")) | AA21: =IF(C21<>"",C21,CONFIG!$B$6) | AB21: =IF(F21<>"",F21,IFERROR(VLOOKUP(AA21,RULES!$A:$C,3,0),CONFIG!$B$7)) | AC21: =IF(IFERROR(VLOOKUP(AA21,RULES!$A:$D,4,0),"")="",CONFIG!$B$10,VLOOKUP(AA21,RULES!$A:$D,4,0)) | AD21: =IF(IFERROR(VLOOKUP(AA21,RULES!$A:$E,5,0),"")="",CONFIG!$B$11,VLOOKUP(AA21,RULES!$A:$E,5,0)) | AE21: =IFERROR(VLOOKUP(AA21,RULES!$A:$F,6,0)*1,0) | AF21: =IFERROR(VLOOKUP(AA21,RULES!$A:$G,7,0)*1,0) | AG21: =IFERROR(VLOOKUP(AA21,RULES!$A:$H,8,0)*1,0) | AH21: =IFERROR(VLOOKUP(AA21,RULES!$A:$I,9,0)*1,0) | AI21: =IFERROR(VLOOKUP(AA21,RULES!$A:$J,10,0)*1,0) | AJ21: =IFERROR(IF(VLOOKUP(AA21,RULES!$A:$K,11,0)="",999999,VLOOKUP(AA21,RULES!$A:$K,11,0)*1),999999) | AK21: =IFERROR(VLOOKUP(AA21,RULES!$A:$L,12,0)*1,0) | AL21: =IFERROR(VLOOKUP(AA21,RULES!$A:$M,13,0),"NONE") | AM21: =IFERROR(VLOOKUP(AA21,RULES!$A:$N,14,0)*1,0) | AN21: =IFERROR(VLOOKUP(AA21,RULES!$A:$O,15,0)*1,0) | AO21: =IF(N21<>"",N21,IFERROR(VLOOKUP(AA21,RULES!$A:$P,16,0),CONFIG!$B$8)) | AP21: =IF(IFERROR(VLOOKUP(AA21,RULES!$A:$Q,17,0),"")="",CONFIG!$B$13,VLOOKUP(AA21,RULES!$A:$Q,17,0)) | AQ21: =IF(IFERROR(VLOOKUP(AA21,RULES!$A:$R,18,0),"")="",CONFIG!$B$14,VLOOKUP(AA21,RULES!$A:$R,18,0)) | AR21: =IFERROR(VLOOKUP(AA21,RULES!$A:$S,19,0)*1,0) | AS21: =IFERROR(VLOOKUP(AA21,RULES!$A:$T,20,0)*1,0) | AT21: =IFERROR(VLOOKUP(AA21,RULES!$A:$U,21,0)*1,0) | AU21: =IFERROR(VLOOKUP(AA21,RULES!$A:$V,22,0)*1,0) | AV21: =IFERROR(VLOOKUP(AA21,RULES!$A:$W,23,0)*1,0) | AW21: =IFERROR(IF(VLOOKUP(AA21,RULES!$A:$X,24,0)="",999999,VLOOKUP(AA21,RULES!$A:$X,24,0)*1),999999) | AX21: =IFERROR(VLOOKUP(AA21,RULES!$A:$Y,25,0)*1,0) | AY21: =IFERROR(VLOOKUP(AA21,RULES!$A:$Z,26,0),"NONE") | AZ21: =IFERROR(VLOOKUP(AA21,RULES!$A:$AA,27,0)*1,0) | BA21: =IFERROR(VLOOKUP(AA21,RULES!$A:$AB,28,0)*1,0)
B22: ACC001 | C22: DEFAULT | E22: =IF(OR(D22="",D22=0),"INACTIVE","ACTIVE") | F22: NORMAL | I22: =IF(OR(E22="INACTIVE",H22=""),0,MAX(0,H22-G22)) | K22: =IF(OR(E22="INACTIVE",H22=""),0,IF(AB22="DISABLED",0,IF(AB22="FLAT",AE22,IF(AB22="MANUAL",IF(J22="",0,J22*AC22),IF(AB22="STEP",IF(I22<=AF22,I22*AG22,IF(I22<=AH22,AF22*AG22+(I22-AF22)*AI22,AF22*AG22+(AH22-AF22)*AI22+(I22-AH22)*AK22)),MAX(I22*AC22,AD22)))))) | L22: =IF(OR(E22="INACTIVE",H22=""),0,IF(AL22="NONE",0,IF(AL22="FLAT",AM22,IF(AL22="PER_UNIT",I22*AN22,IF(AL22="MANUAL",IF(M22="",0,M22),0))))) | N22: NORMAL | Q22: =IF(OR(E22="INACTIVE",P22=""),0,MAX(0,P22-O22)) | S22: =IF(OR(E22="INACTIVE",P22=""),0,IF(AO22="DISABLED",0,IF(AO22="FLAT",AR22,IF(AO22="MANUAL",IF(R22="",0,R22*AP22),IF(AO22="STEP",IF(Q22<=AS22,Q22*AT22,IF(Q22<=AU22,AS22*AT22+(Q22-AS22)*AV22,AS22*AT22+(AU22-AS22)*AV22+(Q22-AU22)*AX22)),MAX(Q22*AP22,AQ22)))))) | T22: =IF(OR(E22="INACTIVE",P22=""),0,IF(AY22="NONE",0,IF(AY22="FLAT",AZ22,IF(AY22="PER_UNIT",Q22*BA22,IF(AY22="MANUAL",IF(U22="",0,U22),0))))) | X22: =IF(E22="INACTIVE",0,D22+K22+L22+S22+T22+IF(V22="",0,V22)+IF(W22="",0,W22)) | Z22: =IF(E22="INACTIVE","_",IF(AND(G22>0,H22>0,H22<G22),"[!]น้ำ reset ","")&IF(AND(O22>0,P22>0,P22<O22),"[!]ไฟ reset ","")&IF(AND(F22="MANUAL",J22=""),"[X]units น้ำ ","")&IF(AND(N22="MANUAL",R22=""),"[X]units ไฟ ","")&IF(D22=0,"[!]ค่าเช่า=0","")) | AA22: =IF(C22<>"",C22,CONFIG!$B$6) | AB22: =IF(F22<>"",F22,IFERROR(VLOOKUP(AA22,RULES!$A:$C,3,0),CONFIG!$B$7)) | AC22: =IF(IFERROR(VLOOKUP(AA22,RULES!$A:$D,4,0),"")="",CONFIG!$B$10,VLOOKUP(AA22,RULES!$A:$D,4,0)) | AD22: =IF(IFERROR(VLOOKUP(AA22,RULES!$A:$E,5,0),"")="",CONFIG!$B$11,VLOOKUP(AA22,RULES!$A:$E,5,0)) | AE22: =IFERROR(VLOOKUP(AA22,RULES!$A:$F,6,0)*1,0) | AF22: =IFERROR(VLOOKUP(AA22,RULES!$A:$G,7,0)*1,0) | AG22: =IFERROR(VLOOKUP(AA22,RULES!$A:$H,8,0)*1,0) | AH22: =IFERROR(VLOOKUP(AA22,RULES!$A:$I,9,0)*1,0) | AI22: =IFERROR(VLOOKUP(AA22,RULES!$A:$J,10,0)*1,0) | AJ22: =IFERROR(IF(VLOOKUP(AA22,RULES!$A:$K,11,0)="",999999,VLOOKUP(AA22,RULES!$A:$K,11,0)*1),999999) | AK22: =IFERROR(VLOOKUP(AA22,RULES!$A:$L,12,0)*1,0) | AL22: =IFERROR(VLOOKUP(AA22,RULES!$A:$M,13,0),"NONE") | AM22: =IFERROR(VLOOKUP(AA22,RULES!$A:$N,14,0)*1,0) | AN22: =IFERROR(VLOOKUP(AA22,RULES!$A:$O,15,0)*1,0) | AO22: =IF(N22<>"",N22,IFERROR(VLOOKUP(AA22,RULES!$A:$P,16,0),CONFIG!$B$8)) | AP22: =IF(IFERROR(VLOOKUP(AA22,RULES!$A:$Q,17,0),"")="",CONFIG!$B$13,VLOOKUP(AA22,RULES!$A:$Q,17,0)) | AQ22: =IF(IFERROR(VLOOKUP(AA22,RULES!$A:$R,18,0),"")="",CONFIG!$B$14,VLOOKUP(AA22,RULES!$A:$R,18,0)) | AR22: =IFERROR(VLOOKUP(AA22,RULES!$A:$S,19,0)*1,0) | AS22: =IFERROR(VLOOKUP(AA22,RULES!$A:$T,20,0)*1,0) | AT22: =IFERROR(VLOOKUP(AA22,RULES!$A:$U,21,0)*1,0) | AU22: =IFERROR(VLOOKUP(AA22,RULES!$A:$V,22,0)*1,0) | AV22: =IFERROR(VLOOKUP(AA22,RULES!$A:$W,23,0)*1,0) | AW22: =IFERROR(IF(VLOOKUP(AA22,RULES!$A:$X,24,0)="",999999,VLOOKUP(AA22,RULES!$A:$X,24,0)*1),999999) | AX22: =IFERROR(VLOOKUP(AA22,RULES!$A:$Y,25,0)*1,0) | AY22: =IFERROR(VLOOKUP(AA22,RULES!$A:$Z,26,0),"NONE") | AZ22: =IFERROR(VLOOKUP(AA22,RULES!$A:$AA,27,0)*1,0) | BA22: =IFERROR(VLOOKUP(AA22,RULES!$A:$AB,28,0)*1,0)
B23: ACC001 | C23: DEFAULT | E23: =IF(OR(D23="",D23=0),"INACTIVE","ACTIVE") | F23: NORMAL | I23: =IF(OR(E23="INACTIVE",H23=""),0,MAX(0,H23-G23)) | K23: =IF(OR(E23="INACTIVE",H23=""),0,IF(AB23="DISABLED",0,IF(AB23="FLAT",AE23,IF(AB23="MANUAL",IF(J23="",0,J23*AC23),IF(AB23="STEP",IF(I23<=AF23,I23*AG23,IF(I23<=AH23,AF23*AG23+(I23-AF23)*AI23,AF23*AG23+(AH23-AF23)*AI23+(I23-AH23)*AK23)),MAX(I23*AC23,AD23)))))) | L23: =IF(OR(E23="INACTIVE",H23=""),0,IF(AL23="NONE",0,IF(AL23="FLAT",AM23,IF(AL23="PER_UNIT",I23*AN23,IF(AL23="MANUAL",IF(M23="",0,M23),0))))) | N23: NORMAL | Q23: =IF(OR(E23="INACTIVE",P23=""),0,MAX(0,P23-O23)) | S23: =IF(OR(E23="INACTIVE",P23=""),0,IF(AO23="DISABLED",0,IF(AO23="FLAT",AR23,IF(AO23="MANUAL",IF(R23="",0,R23*AP23),IF(AO23="STEP",IF(Q23<=AS23,Q23*AT23,IF(Q23<=AU23,AS23*AT23+(Q23-AS23)*AV23,AS23*AT23+(AU23-AS23)*AV23+(Q23-AU23)*AX23)),MAX(Q23*AP23,AQ23)))))) | T23: =IF(OR(E23="INACTIVE",P23=""),0,IF(AY23="NONE",0,IF(AY23="FLAT",AZ23,IF(AY23="PER_UNIT",Q23*BA23,IF(AY23="MANUAL",IF(U23="",0,U23),0))))) | X23: =IF(E23="INACTIVE",0,D23+K23+L23+S23+T23+IF(V23="",0,V23)+IF(W23="",0,W23)) | Z23: =IF(E23="INACTIVE","_",IF(AND(G23>0,H23>0,H23<G23),"[!]น้ำ reset ","")&IF(AND(O23>0,P23>0,P23<O23),"[!]ไฟ reset ","")&IF(AND(F23="MANUAL",J23=""),"[X]units น้ำ ","")&IF(AND(N23="MANUAL",R23=""),"[X]units ไฟ ","")&IF(D23=0,"[!]ค่าเช่า=0","")) | AA23: =IF(C23<>"",C23,CONFIG!$B$6) | AB23: =IF(F23<>"",F23,IFERROR(VLOOKUP(AA23,RULES!$A:$C,3,0),CONFIG!$B$7)) | AC23: =IF(IFERROR(VLOOKUP(AA23,RULES!$A:$D,4,0),"")="",CONFIG!$B$10,VLOOKUP(AA23,RULES!$A:$D,4,0)) | AD23: =IF(IFERROR(VLOOKUP(AA23,RULES!$A:$E,5,0),"")="",CONFIG!$B$11,VLOOKUP(AA23,RULES!$A:$E,5,0)) | AE23: =IFERROR(VLOOKUP(AA23,RULES!$A:$F,6,0)*1,0) | AF23: =IFERROR(VLOOKUP(AA23,RULES!$A:$G,7,0)*1,0) | AG23: =IFERROR(VLOOKUP(AA23,RULES!$A:$H,8,0)*1,0) | AH23: =IFERROR(VLOOKUP(AA23,RULES!$A:$I,9,0)*1,0) | AI23: =IFERROR(VLOOKUP(AA23,RULES!$A:$J,10,0)*1,0) | AJ23: =IFERROR(IF(VLOOKUP(AA23,RULES!$A:$K,11,0)="",999999,VLOOKUP(AA23,RULES!$A:$K,11,0)*1),999999) | AK23: =IFERROR(VLOOKUP(AA23,RULES!$A:$L,12,0)*1,0) | AL23: =IFERROR(VLOOKUP(AA23,RULES!$A:$M,13,0),"NONE") | AM23: =IFERROR(VLOOKUP(AA23,RULES!$A:$N,14,0)*1,0) | AN23: =IFERROR(VLOOKUP(AA23,RULES!$A:$O,15,0)*1,0) | AO23: =IF(N23<>"",N23,IFERROR(VLOOKUP(AA23,RULES!$A:$P,16,0),CONFIG!$B$8)) | AP23: =IF(IFERROR(VLOOKUP(AA23,RULES!$A:$Q,17,0),"")="",CONFIG!$B$13,VLOOKUP(AA23,RULES!$A:$Q,17,0)) | AQ23: =IF(IFERROR(VLOOKUP(AA23,RULES!$A:$R,18,0),"")="",CONFIG!$B$14,VLOOKUP(AA23,RULES!$A:$R,18,0)) | AR23: =IFERROR(VLOOKUP(AA23,RULES!$A:$S,19,0)*1,0) | AS23: =IFERROR(VLOOKUP(AA23,RULES!$A:$T,20,0)*1,0) | AT23: =IFERROR(VLOOKUP(AA23,RULES!$A:$U,21,0)*1,0) | AU23: =IFERROR(VLOOKUP(AA23,RULES!$A:$V,22,0)*1,0) | AV23: =IFERROR(VLOOKUP(AA23,RULES!$A:$W,23,0)*1,0) | AW23: =IFERROR(IF(VLOOKUP(AA23,RULES!$A:$X,24,0)="",999999,VLOOKUP(AA23,RULES!$A:$X,24,0)*1),999999) | AX23: =IFERROR(VLOOKUP(AA23,RULES!$A:$Y,25,0)*1,0) | AY23: =IFERROR(VLOOKUP(AA23,RULES!$A:$Z,26,0),"NONE") | AZ23: =IFERROR(VLOOKUP(AA23,RULES!$A:$AA,27,0)*1,0) | BA23: =IFERROR(VLOOKUP(AA23,RULES!$A:$AB,28,0)*1,0)
